Workbook
Name Slicer_Date: #N/A
Name Slicer_Date1: #N/A
Name Slicer_Party: #N/A
Name Slicer_Party_Name: #N/A
Name Slicer_Party_Name1: #N/A
Name Slicer_Party_Name2: #N/A
Name Slicer_Person: #N/A
Name Slicer_Shipment_Number: #N/A

Sheet Billing
B1: Party Name | C1: Tiyaar | D1: Rate | E1: Total | G1: Billing
B2: =B57 -> BSC | C2: =SUMIFS(ledger!G:G, ledger!B:B, B2, ledger!E:E, "<>*RD*") / 1.0936 -> 1315881.5 | D2: 10 | E2: =(SUMIFS(ledger!G:G, ledger!B:B, B2, ledger!E:E, "<>*RD*",ledger!D:D, "Silky") / 1.0936)*12 + (SUMIFS(ledger!G:G, ledger!B:B, B2, ledger!E:E, "<>*RD*",ledger!D:D, "Chamki") / 1.0936)*10 -> 12508742 | I2: BSC | S2: Billing Total
B3: =B58 -> Ejaz Sahab | C3: =SUMIFS(ledger!G:G, ledger!B:B, B3, ledger!E:E, "<>*RD*") / 1.0936 -> 49525.421 | D3: 10 | E3: =(SUMIFS(ledger!G:G, ledger!B:B, B3, ledger!E:E, "<>*RD*",ledger!D:D, "Silky") / 1.0936)*12 + (SUMIFS(ledger!G:G, ledger!B:B, B3, ledger!E:E, "<>*RD*",ledger!D:D, "Chamki") / 1.0936)*10 -> 594305.05 | I3: Ejaz Sahab
B4: =B59 -> Arshad | C4: =SUMIFS(ledger!G:G, ledger!B:B, B4, ledger!E:E, "<>*RD*") / 1.0936 -> 77906.913 | D4: 10 | E4: =(SUMIFS(ledger!G:G, ledger!B:B, B4, ledger!E:E, "<>*RD*",ledger!D:D, "Silky") / 1.0936)*12 + (SUMIFS(ledger!G:G, ledger!B:B, B4, ledger!E:E, "<>*RD*",ledger!D:D, "Chamki") / 1.0936)*10 -> 779069.13 | I4: Arshad | T4: Gaz | U4: Total Metres | V4: Total Chamki | W4: Total Super Silky | X4: Billing (Chamki/Crinkle) | Y4: Billing (Super Chamki) | Z4: Billing (Slub) | AA4: Billing (Satin) | AB4: Billing (Black-chamki) | AC4: Billing (Kataan) | AD4: Billing (Munaar) | AE4: Billing (Super kataan) | AF4: Billing (Custom) | AG4: Adjusted Bill | AH4: Amount Paid | AI4: Balance | AJ4: Rate (Chamki) | AK4: Rate (Super Silky) | AN4: SUM
B5: =B60 -> Shehzad Kamoki | C5: =SUMIFS(ledger!G:G, ledger!B:B, B5, ledger!E:E, "<>*RD*") / 1.0936 -> 0 | D5: 10.5 | E5: =(SUMIFS(ledger!G:G, ledger!B:B, B5, ledger!E:E, "<>*RD*",ledger!D:D, "Silky") / 1.0936)*12 + (SUMIFS(ledger!G:G, ledger!B:B, B5, ledger!E:E, "<>*RD*",ledger!D:D, "Chamki") / 1.0936)*10.5 -> 0 | I5: Shehzad Kamoki | S5: {=_xlfn.UNIQUE(Table1[Party Name])} -> BSC | T5: {=_xlfn.BYROW(B57,_xlfn.LAMBDA(_xlpm.party,SUMIFS(ledger!G:G,ledger!B:B,_xlpm.party,ledger!E:E,"<>*RD*")))+_xlfn.IFNA(C126,0)} -> 5785561.9 | U5: {=_xlfn.BYROW(B57, _xlfn.LAMBDA(_xlpm.party, SUMIFS(ledger!G:G, ledger!B:B, _xlpm.party, ledger!E:E, "<>*RD*") / 1.0936 ))+_xlfn.IFNA(E126,0)} -> 4442568.5 | V5: {=(_xlfn.BYROW(B57,_xlfn.LAMBDA(_xlpm.party,SUMIFS(ledger!G:G,ledger!B:B,_xlpm.party,ledger!E:E,"<>*RD*",ledger!D:D,"Chamki")+SUMIFS(ledger!G:G, ledger!B:B, _xlpm.party, ledger!E:E, "<>*RD*", ledger!D:D, "Crinkle")))/1.0936)+_xlfn.IFNA(E126,0)} -> 3957426.7 | W5: {=(_xlfn.BYROW(B57,_xlfn.LAMBDA(_xlpm.party,SUMIFS(ledger!G:G,ledger!B:B,_xlpm.party,ledger!E:E,"<>*RD*",ledger!D:D,"Silky")))/1.0936)+_xlfn.IFNA(F126,0)} -> 1138082.5 | X5: {=(_xlfn.BYROW(B57,_xlfn.LAMBDA(_xlpm.party, (SUMIFS(ledger!J:J,ledger!B:B,_xlpm.party,ledger!E:E,"<>*RD*",ledger!D:D,"Chamki",ledger!C:C,"<>Closing CF")+ SUMIFS(ledger!J:J,ledger!B:B,_xlpm.party,ledger!E:E,"<>*RD*",ledger!D:D,"Crinkle",ledger!C:C,"<>Closing CF") )+_xlfn.IFNA(G126,0))))} -> 39574267 | Y5: {=_xlfn.BYROW(B57, _xlfn.LAMBDA(_xlpm.party, SUMIFS(ledger!J:J, ledger!B:B, _xlpm.party, ledger!E:E, "<>*RD*", ledger!D:D, "Silky", ledger!C:C, "<>Closing CF") )) + _xlfn.IFNA(H126, 0)} -> 14443232 | Z5: {=_xlfn.BYROW(B57, _xlfn.LAMBDA(_xlpm.party, SUMIFS(ledger!J:J, ledger!B:B, _xlpm.party, ledger!E:E, "<>*RD*", ledger!D:D, "Slub", ledger!C:C, "<>Closing CF") ))+ _xlfn.IFNA(I126, 0)} -> 0 | AA5: {=_xlfn.BYROW(B57, _xlfn.LAMBDA(_xlpm.party, SUMIFS(ledger!J:J, ledger!B:B, _xlpm.party, ledger!E:E, "<>*RD*", ledger!D:D, "Satin", ledger!C:C, "<>Closing CF") ))+ _xlfn.IFNA(J126, 0)} -> 0 | AB5: {=_xlfn.BYROW(B57, _xlfn.LAMBDA(_xlpm.party, SUMIFS(ledger!J:J, ledger!B:B, _xlpm.party, ledger!E:E, "<>*RD*", ledger!D:D, "Black-Chamki", ledger!C:C, "<>Closing CF") ))+ _xlfn.IFNA(K126, 0)} -> 0 | AC5: {=_xlfn.BYROW(B57, _xlfn.LAMBDA(_xlpm.party, SUMIFS(ledger!J:J, ledger!B:B, _xlpm.party, ledger!E:E, "<>*RD*", ledger!D:D, "Kataan", ledger!C:C, "<>Closing CF") ))+ _xlfn.IFNA(L126, 0)} -> 2127095.8 | AD5: {=_xlfn.BYROW(B57, _xlfn.LAMBDA(_xlpm.party, SUMIFS(ledger!J:J, ledger!B:B, _xlpm.party, ledger!E:E, "<>*RD*", ledger!D:D, "Munaar", ledger!C:C, "<>Closing CF") ))+ _xlfn.IFNA(M126, 0)} -> 0 | AE5: {=_xlfn.BYROW(B57, _xlfn.LAMBDA(_xlpm.party, SUMIFS(ledger!J:J, ledger!B:B, _xlpm.party, ledger!E:E, "<>*RD*", ledger!D:D, "Super Kataan", ledger!C:C, "<>Closing CF") ))+ _xlfn.IFNA(N126, 0)} -> 0 | AF5: {=_xlfn.BYROW(B57, _xlfn.LAMBDA(_xlpm.party, SUMIFS(ledger!J:J, ledger!B:B, _xlpm.party, ledger!E:E, "<>*RD*", ledger!D:D, "Custom", ledger!C:C, "<>Closing CF") ))+ _xlfn.IFNA(O126, 0)} -> 18006.584 | AG5: =X5+Y5+Z5+AA5+AB5+AC5+AD5+AF5+AE5 -> 56162601 | AH5: =(SUMIF(Table14[Party],#REF!,Table14[Credit]))+_xlfn.IFNA(Q126,0) -> 19750734 | AI5: =AG5-AH5 -> 36411867 | AJ5: 10 | AK5: 13 | AN5: =SUM(AI5:AI47) -> 42660365
B6: =B61 -> Sufi Nawaz Sahab | C6: =SUMIFS(ledger!G:G, ledger!B:B, B6, ledger!E:E, "<>*RD*") / 1.0936 -> 160812 | D6: 10 | E6: =((SUMIFS(ledger!G:G, ledger!B:B, B6, ledger!E:E, "<>*RD*",ledger!D:D, "Silky") / 1.0936) *12) + ((SUMIFS(ledger!G:G, ledger!B:B, B6, ledger!E:E, "<>*RD*",ledger!D:D, "Chamki") / 1.0936)* 9) -> 1198266.3 | I6: Sufi Nawaz Sahab | S6: Ejaz Sahab | T6: {=_xlfn.BYROW(B58,_xlfn.LAMBDA(_xlpm.party,SUMIFS(ledger!G:G,ledger!B:B,_xlpm.party,ledger!E:E,"<>*RD*")))+_xlfn.IFNA(C127,0)} -> 703440 | U6: {=_xlfn.BYROW(B58, _xlfn.LAMBDA(_xlpm.party, SUMIFS(ledger!G:G, ledger!B:B, _xlpm.party, ledger!E:E, "<>*RD*") / 1.0936 ))+_xlfn.IFNA(D127,0)} -> 643233.36 | V6: {=(_xlfn.BYROW(B58,_xlfn.LAMBDA(_xlpm.party,SUMIFS(ledger!G:G,ledger!B:B,_xlpm.party,ledger!E:E,"<>*RD*",ledger!D:D,"Chamki")+SUMIFS(ledger!G:G, ledger!B:B, _xlpm.party, ledger!E:E, "<>*RD*", ledger!D:D, "Crinkle")))/1.0936)+_xlfn.IFNA(E127,0)} -> 148145.57 | W6: {=(_xlfn.BYROW(B58,_xlfn.LAMBDA(_xlpm.party,SUMIFS(ledger!G:G,ledger!B:B,_xlpm.party,ledger!E:E,"<>*RD*",ledger!D:D,"Silky")))/1.0936)+_xlfn.IFNA(F127,0)} -> 495087.78 | X6: {=(_xlfn.BYROW(B58,_xlfn.LAMBDA(_xlpm.party, (SUMIFS(ledger!J:J,ledger!B:B,_xlpm.party,ledger!E:E,"<>*RD*",ledger!D:D,"Chamki",ledger!C:C,"<>Closing CF")+ SUMIFS(ledger!J:J,ledger!B:B,_xlpm.party,ledger!E:E,"<>*RD*",ledger!D:D,"Crinkle",ledger!C:C,"<>Closing CF") )+_xlfn.IFNA(G127,0))))} -> 1481455.7 | Y6: {=_xlfn.BYROW(B58, _xlfn.LAMBDA(_xlpm.party, SUMIFS(ledger!J:J, ledger!B:B, _xlpm.party, ledger!E:E, "<>*RD*", ledger!D:D, "Silky", ledger!C:C, "<>Closing CF") )) + _xlfn.IFNA(H127, 0)} -> 6376997.1 | Z6: {=_xlfn.BYROW(B58, _xlfn.LAMBDA(_xlpm.party, SUMIFS(ledger!J:J, ledger!B:B, _xlpm.party, ledger!E:E, "<>*RD*", ledger!D:D, "Slub", ledger!C:C, "<>Closing CF") ))+ _xlfn.IFNA(I127, 0)} -> 0 | AA6: {=_xlfn.BYROW(B58, _xlfn.LAMBDA(_xlpm.party, SUMIFS(ledger!J:J, ledger!B:B, _xlpm.party, ledger!E:E, "<>*RD*", ledger!D:D, "Satin", ledger!C:C, "<>Closing CF") ))+ _xlfn.IFNA(J127, 0)} -> 0 | AB6: {=_xlfn.BYROW(B58, _xlfn.LAMBDA(_xlpm.party, SUMIFS(ledger!J:J, ledger!B:B, _xlpm.party, ledger!E:E, "<>*RD*", ledger!D:D, "Black-Chamki", ledger!C:C, "<>Closing CF") ))+ _xlfn.IFNA(K127, 0)} -> 0 | AC6: {=_xlfn.BYROW(B58, _xlfn.LAMBDA(_xlpm.party, SUMIFS(ledger!J:J, ledger!B:B, _xlpm.party, ledger!E:E, "<>*RD*", ledger!D:D, "Kataan", ledger!C:C, "<>Closing CF") ))+ _xlfn.IFNA(L127, 0)} -> 0 | AD6: {=_xlfn.BYROW(B58, _xlfn.LAMBDA(_xlpm.party, SUMIFS(ledger!J:J, ledger!B:B, _xlpm.party, ledger!E:E, "<>*RD*", ledger!D:D, "Munaar", ledger!C:C, "<>Closing CF") ))+ _xlfn.IFNA(M127, 0)} -> 0 | AE6: {=_xlfn.BYROW(B58, _xlfn.LAMBDA(_xlpm.party, SUMIFS(ledger!J:J, ledger!B:B, _xlpm.party, ledger!E:E, "<>*RD*", ledger!D:D, "Super Kataan", ledger!C:C, "<>Closing CF") ))+ _xlfn.IFNA(N127, 0)} -> 0 | AF6: {=_xlfn.BYROW(B58, _xlfn.LAMBDA(_xlpm.party, SUMIFS(ledger!J:J, ledger!B:B, _xlpm.party, ledger!E:E, "<>*RD*", ledger!D:D, "Custom", ledger!C:C, "<>Closing CF") ))+ _xlfn.IFNA(O127, 0)} -> 0 | AG6: =X6+Y6+Z6+AA6+AB6+AC6+AD6+AF6+AE6 -> 7858452.8 | AH6: =(SUMIF(Table14[Party],S6,Table14[Credit]))+_xlfn.IFNA(Q127,0) -> 7214622 | AI6: =AG6-AH6 -> 643830.82 | AJ6: 10 | AK6: 13
B7: =B62 -> Sajad Khan | C7: =SUMIFS(ledger!G:G, ledger!B:B, B7, ledger!E:E, "<>*RD*") / 1.0936 -> 0 | D7: 10 | E7: {=(SUMIFS(ledger!G:G, ledger!B:B, B7, ledger!E:E, "<>*RD*",ledger!D:D, "Silky") / 1.0936)*12 + (SUMIFS(ledger!G:G, ledger!B:B, B7, ledger!E:E, "<>*RD*",ledger!D:D, "Chamki") / 1.0936)*10 +(SUMIFS(ledger!G:G, ledger!B:B, party, ledger!E:E, "<>*RD*", ledger!D:D, "Crinkle")/ 1.0936)*10} -> 0 | I7: Sajad Khan | S7: Arshad | T7: {=_xlfn.BYROW(B59,_xlfn.LAMBDA(_xlpm.party,SUMIFS(ledger!G:G,ledger!B:B,_xlpm.party,ledger!E:E,"<>*RD*")))+_xlfn.IFNA(C128,0)} -> 1052426 | U7: {=_xlfn.BYROW(B59, _xlfn.LAMBDA(_xlpm.party, SUMIFS(ledger!G:G, ledger!B:B, _xlpm.party, ledger!E:E, "<>*RD*") / 1.0936 ))+_xlfn.IFNA(D128,0)} -> 962350.04 | V7: {=(_xlfn.BYROW(B59,_xlfn.LAMBDA(_xlpm.party,SUMIFS(ledger!G:G,ledger!B:B,_xlpm.party,ledger!E:E,"<>*RD*",ledger!D:D,"Chamki")+SUMIFS(ledger!G:G, ledger!B:B, _xlpm.party, ledger!E:E, "<>*RD*", ledger!D:D, "Crinkle")))/1.0936)+_xlfn.IFNA(E128,0)} -> 796824.25 | W7: {=(_xlfn.BYROW(B59,_xlfn.LAMBDA(_xlpm.party,SUMIFS(ledger!G:G,ledger!B:B,_xlpm.party,ledger!E:E,"<>*RD*",ledger!D:D,"Silky")))/1.0936)+_xlfn.IFNA(F128,0)} -> 165525.79 | X7: {=(_xlfn.BYROW(B59,_xlfn.LAMBDA(_xlpm.party, (SUMIFS(ledger!J:J,ledger!B:B,_xlpm.party,ledger!E:E,"<>*RD*",ledger!D:D,"Chamki",ledger!C:C,"<>Closing CF")+ SUMIFS(ledger!J:J,ledger!B:B,_xlpm.party,ledger!E:E,"<>*RD*",ledger!D:D,"Crinkle",ledger!C:C,"<>Closing CF") )+_xlfn.IFNA(G128,0))))} -> 7968242.5 | Y7: {=_xlfn.BYROW(B59, _xlfn.LAMBDA(_xlpm.party, SUMIFS(ledger!J:J, ledger!B:B, _xlpm.party, ledger!E:E, "<>*RD*", ledger!D:D, "Silky", ledger!C:C, "<>Closing CF") )) + _xlfn.IFNA(H128, 0)} -> 2137041 | Z7: {=_xlfn.BYROW(B59, _xlfn.LAMBDA(_xlpm.party, SUMIFS(ledger!J:J, ledger!B:B, _xlpm.party, ledger!E:E, "<>*RD*", ledger!D:D, "Slub", ledger!C:C, "<>Closing CF") ))+ _xlfn.IFNA(I128, 0)} -> 0 | AA7: {=_xlfn.BYROW(B59, _xlfn.LAMBDA(_xlpm.party, SUMIFS(ledger!J:J, ledger!B:B, _xlpm.party, ledger!E:E, "<>*RD*", ledger!D:D, "Satin", ledger!C:C, "<>Closing CF") ))+ _xlfn.IFNA(J128, 0)} -> 0 | AB7: {=_xlfn.BYROW(B59, _xlfn.LAMBDA(_xlpm.party, SUMIFS(ledger!J:J, ledger!B:B, _xlpm.party, ledger!E:E, "<>*RD*", ledger!D:D, "Black-Chamki", ledger!C:C, "<>Closing CF") ))+ _xlfn.IFNA(K128, 0)} -> 0 | AC7: {=_xlfn.BYROW(B59, _xlfn.LAMBDA(_xlpm.party, SUMIFS(ledger!J:J, ledger!B:B, _xlpm.party, ledger!E:E, "<>*RD*", ledger!D:D, "Kataan", ledger!C:C, "<>Closing CF") ))+ _xlfn.IFNA(L128, 0)} -> 0 | AD7: {=_xlfn.BYROW(B59, _xlfn.LAMBDA(_xlpm.party, SUMIFS(ledger!J:J, ledger!B:B, _xlpm.party, ledger!E:E, "<>*RD*", ledger!D:D, "Munaar", ledger!C:C, "<>Closing CF") ))+ _xlfn.IFNA(M128, 0)} -> 0 | AE7: {=_xlfn.BYROW(B59, _xlfn.LAMBDA(_xlpm.party, SUMIFS(ledger!J:J, ledger!B:B, _xlpm.party, ledger!E:E, "<>*RD*", ledger!D:D, "Super Kataan", ledger!C:C, "<>Closing CF") ))+ _xlfn.IFNA(N128, 0)} -> 0 | AF7: {=_xlfn.BYROW(B59, _xlfn.LAMBDA(_xlpm.party, SUMIFS(ledger!J:J, ledger!B:B, _xlpm.party, ledger!E:E, "<>*RD*", ledger!D:D, "Custom", ledger!C:C, "<>Closing CF") ))+ _xlfn.IFNA(O128, 0)} -> 0 | AG7: =X7+Y7+Z7+AA7+AB7+AC7+AD7+AF7+AE7 -> 10105283 | AH7: =(SUMIF(Table14[Party],S7,Table14[Credit]))+_xlfn.IFNA(Q128,0) -> 9812586 | AI7: =AG7-AH7 -> 292697.47 | AJ7: 10 | AK7: 13
B8: =B63 -> Raaz Fabrics | C8: =SUMIFS(ledger!G:G, ledger!B:B, B8, ledger!E:E, "<>*RD*") / 1.0936 -> 73510.424 | D8: 10 | E8: =(SUMIFS(ledger!G:G, ledger!B:B, B8, ledger!E:E, "<>*RD*",ledger!D:D, "Silky") / 1.0936)*12 + (SUMIFS(ledger!G:G, ledger!B:B, B8, ledger!E:E, "<>*RD*",ledger!D:D, "chamki") / 1.0936)*10 +(SUMIFS(ledger!G:G, ledger!B:B, B8, ledger!E:E, "<>*RD*",ledger!D:D, "Crinkle") / 1.0936)*10 -> 735104.24 | I8: Raaz Fabrics | S8: Shehzad Kamoki | T8: {=_xlfn.BYROW(B60,_xlfn.LAMBDA(_xlpm.party,SUMIFS(ledger!G:G,ledger!B:B,_xlpm.party,ledger!E:E,"<>*RD*")))+_xlfn.IFNA(C129,0)} -> 143457 | U8: {=_xlfn.BYROW(B60, _xlfn.LAMBDA(_xlpm.party, SUMIFS(ledger!G:G, ledger!B:B, _xlpm.party, ledger!E:E, "<>*RD*") / 1.0936 ))+_xlfn.IFNA(D129,0)} -> 131178.68 | V8: {=(_xlfn.BYROW(B60,_xlfn.LAMBDA(_xlpm.party,SUMIFS(ledger!G:G,ledger!B:B,_xlpm.party,ledger!E:E,"<>*RD*",ledger!D:D,"Chamki")+SUMIFS(ledger!G:G, ledger!B:B, _xlpm.party, ledger!E:E, "<>*RD*", ledger!D:D, "Crinkle")))/1.0936)+_xlfn.IFNA(E129,0)} -> 131178.68 | W8: {=(_xlfn.BYROW(B60,_xlfn.LAMBDA(_xlpm.party,SUMIFS(ledger!G:G,ledger!B:B,_xlpm.party,ledger!E:E,"<>*RD*",ledger!D:D,"Silky")))/1.0936)+_xlfn.IFNA(F129,0)} -> 0 | X8: {=(_xlfn.BYROW(B60,_xlfn.LAMBDA(_xlpm.party, (SUMIFS(ledger!J:J,ledger!B:B,_xlpm.party,ledger!E:E,"<>*RD*",ledger!D:D,"Chamki",ledger!C:C,"<>Closing CF")+ SUMIFS(ledger!J:J,ledger!B:B,_xlpm.party,ledger!E:E,"<>*RD*",ledger!D:D,"Crinkle",ledger!C:C,"<>Closing CF") )+_xlfn.IFNA(G129,0))))} -> 1354242 | Y8: {=_xlfn.BYROW(B60, _xlfn.LAMBDA(_xlpm.party, SUMIFS(ledger!J:J, ledger!B:B, _xlpm.party, ledger!E:E, "<>*RD*", ledger!D:D, "Silky", ledger!C:C, "<>Closing CF") )) + _xlfn.IFNA(H129, 0)} -> 0 | Z8: {=_xlfn.BYROW(B60, _xlfn.LAMBDA(_xlpm.party, SUMIFS(ledger!J:J, ledger!B:B, _xlpm.party, ledger!E:E, "<>*RD*", ledger!D:D, "Slub", ledger!C:C, "<>Closing CF") ))+ _xlfn.IFNA(I129, 0)} -> 0 | AA8: {=_xlfn.BYROW(B60, _xlfn.LAMBDA(_xlpm.party, SUMIFS(ledger!J:J, ledger!B:B, _xlpm.party, ledger!E:E, "<>*RD*", ledger!D:D, "Satin", ledger!C:C, "<>Closing CF") ))+ _xlfn.IFNA(J129, 0)} -> 0 | AB8: {=_xlfn.BYROW(B60, _xlfn.LAMBDA(_xlpm.party, SUMIFS(ledger!J:J, ledger!B:B, _xlpm.party, ledger!E:E, "<>*RD*", ledger!D:D, "Black-Chamki", ledger!C:C, "<>Closing CF") ))+ _xlfn.IFNA(K129, 0)} -> 0 | AC8: {=_xlfn.BYROW(B60, _xlfn.LAMBDA(_xlpm.party, SUMIFS(ledger!J:J, ledger!B:B, _xlpm.party, ledger!E:E, "<>*RD*", ledger!D:D, "Kataan", ledger!C:C, "<>Closing CF") ))+ _xlfn.IFNA(L129, 0)} -> 0 | AD8: {=_xlfn.BYROW(B60, _xlfn.LAMBDA(_xlpm.party, SUMIFS(ledger!J:J, ledger!B:B, _xlpm.party, ledger!E:E, "<>*RD*", ledger!D:D, "Munaar", ledger!C:C, "<>Closing CF") ))+ _xlfn.IFNA(M129, 0)} -> 0 | AE8: {=_xlfn.BYROW(B60, _xlfn.LAMBDA(_xlpm.party, SUMIFS(ledger!J:J, ledger!B:B, _xlpm.party, ledger!E:E, "<>*RD*", ledger!D:D, "Super Kataan", ledger!C:C, "<>Closing CF") ))+ _xlfn.IFNA(N129, 0)} -> 0 | AF8: {=_xlfn.BYROW(B60, _xlfn.LAMBDA(_xlpm.party, SUMIFS(ledger!J:J, ledger!B:B, _xlpm.party, ledger!E:E, "<>*RD*", ledger!D:D, "Custom", ledger!C:C, "<>Closing CF") ))+ _xlfn.IFNA(O129, 0)} -> 0 | AG8: =X8+Y8+Z8+AA8+AB8+AC8+AD8+AF8+AE8 -> 1354242 | AH8: =(SUMIF(Table14[Party],S8,Table14[Credit]))+_xlfn.IFNA(Q129,0) -> 1353710 | AI8: =AG8-AH8 -> 531.99729 | AJ8: 10.5 | AK8: 13
B9: =B64 -> Azam | C9: =SUMIFS(ledger!G:G, ledger!B:B, B9, ledger!E:E, "<>*RD*") / 1.0936 -> 0 | D9: 10 | E9: =(SUMIFS(ledger!G:G, ledger!B:B, B9, ledger!E:E, "<>*RD*",ledger!D:D, "Silky") / 1.0936)*12 + (SUMIFS(ledger!G:G, ledger!B:B, B9, ledger!E:E, "<>*RD*",ledger!D:D, "Chamki") / 1.0936)*10 -> 0 | I9: Azam | S9: Sufi Nawaz Sahab | T9: {=_xlfn.BYROW(B61,_xlfn.LAMBDA(_xlpm.party,SUMIFS(ledger!G:G,ledger!B:B,_xlpm.party,ledger!E:E,"<>*RD*")))+_xlfn.IFNA(C130,0)} -> 1388831 | U9: {=_xlfn.BYROW(B61, _xlfn.LAMBDA(_xlpm.party, SUMIFS(ledger!G:G, ledger!B:B, _xlpm.party, ledger!E:E, "<>*RD*") / 1.0936 ))+_xlfn.IFNA(D130,0)} -> 1269962.5 | V9: {=(_xlfn.BYROW(B61,_xlfn.LAMBDA(_xlpm.party,SUMIFS(ledger!G:G,ledger!B:B,_xlpm.party,ledger!E:E,"<>*RD*",ledger!D:D,"Chamki")+SUMIFS(ledger!G:G, ledger!B:B, _xlpm.party, ledger!E:E, "<>*RD*", ledger!D:D, "Crinkle")))/1.0936)+_xlfn.IFNA(E130,0)} -> 599330.65 | W9: {=(_xlfn.BYROW(B61,_xlfn.LAMBDA(_xlpm.party,SUMIFS(ledger!G:G,ledger!B:B,_xlpm.party,ledger!E:E,"<>*RD*",ledger!D:D,"Silky")))/1.0936)+_xlfn.IFNA(F130,0)} -> 585679.41 | X9: {=(_xlfn.BYROW(B61,_xlfn.LAMBDA(_xlpm.party, (SUMIFS(ledger!J:J,ledger!B:B,_xlpm.party,ledger!E:E,"<>*RD*",ledger!D:D,"Chamki",ledger!C:C,"<>Closing CF")+ SUMIFS(ledger!J:J,ledger!B:B,_xlpm.party,ledger!E:E,"<>*RD*",ledger!D:D,"Crinkle",ledger!C:C,"<>Closing CF") )+_xlfn.IFNA(G130,0))))} -> 5408917.9 | Y9: {=_xlfn.BYROW(B61, _xlfn.LAMBDA(_xlpm.party, SUMIFS(ledger!J:J, ledger!B:B, _xlpm.party, ledger!E:E, "<>*RD*", ledger!D:D, "Silky", ledger!C:C, "<>Closing CF") )) + _xlfn.IFNA(H130, 0)} -> 6928297.4 | Z9: {=_xlfn.BYROW(B61, _xlfn.LAMBDA(_xlpm.party, SUMIFS(ledger!J:J, ledger!B:B, _xlpm.party, ledger!E:E, "<>*RD*", ledger!D:D, "Slub", ledger!C:C, "<>Closing CF") ))+ _xlfn.IFNA(I130, 0)} -> 0 | AA9: {=_xlfn.BYROW(B61, _xlfn.LAMBDA(_xlpm.party, SUMIFS(ledger!J:J, ledger!B:B, _xlpm.party, ledger!E:E, "<>*RD*", ledger!D:D, "Satin", ledger!C:C, "<>Closing CF") ))+ _xlfn.IFNA(J130, 0)} -> 239959.77 | AB9: {=_xlfn.BYROW(B61, _xlfn.LAMBDA(_xlpm.party, SUMIFS(ledger!J:J, ledger!B:B, _xlpm.party, ledger!E:E, "<>*RD*", ledger!D:D, "Black-Chamki", ledger!C:C, "<>Closing CF") ))+ _xlfn.IFNA(K130, 0)} -> 0 | AC9: {=_xlfn.BYROW(B61, _xlfn.LAMBDA(_xlpm.party, SUMIFS(ledger!J:J, ledger!B:B, _xlpm.party, ledger!E:E, "<>*RD*", ledger!D:D, "Kataan", ledger!C:C, "<>Closing CF") ))+ _xlfn.IFNA(L130, 0)} -> 0 | AD9: {=_xlfn.BYROW(B61, _xlfn.LAMBDA(_xlpm.party, SUMIFS(ledger!J:J, ledger!B:B, _xlpm.party, ledger!E:E, "<>*RD*", ledger!D:D, "Munaar", ledger!C:C, "<>Closing CF") ))+ _xlfn.IFNA(M130, 0)} -> 0 | AE9: {=_xlfn.BYROW(B61, _xlfn.LAMBDA(_xlpm.party, SUMIFS(ledger!J:J, ledger!B:B, _xlpm.party, ledger!E:E, "<>*RD*", ledger!D:D, "Super Kataan", ledger!C:C, "<>Closing CF") ))+ _xlfn.IFNA(N130, 0)} -> 914347.11 | AF9: {=_xlfn.BYROW(B61, _xlfn.LAMBDA(_xlpm.party, SUMIFS(ledger!J:J, ledger!B:B, _xlpm.party, ledger!E:E, "<>*RD*", ledger!D:D, "Custom", ledger!C:C, "<>Closing CF") ))+ _xlfn.IFNA(O130, 0)} -> 0 | AG9: =X9+Y9+Z9+AA9+AB9+AC9+AD9+AF9+AE9 -> 13491522 | AH9: =(SUMIF(Table14[Party],S9,Table14[Credit]))+_xlfn.IFNA(Q130,0) -> 12178764 | AI9: =AG9-AH9 -> 1312758.1 | AJ9: 10 | AK9: 13
B10: =B65 -> Ubaidullah | C10: =SUMIFS(ledger!G:G, ledger!B:B, B10, ledger!E:E, "<>*RD*") / 1.0936 -> 149238.3 | D10: 10 | E10: =(SUMIFS(ledger!G:G, ledger!B:B, B10, ledger!E:E, "<>*RD*",ledger!D:D, "Silky") / 1.0936)*12 + (SUMIFS(ledger!G:G, ledger!B:B, B10, ledger!E:E, "<>*RD*",ledger!D:D, "Chamki") / 1.0936)*10 -> 1790859.5 | I10: Ubaidullah | S10: Sajad Khan | T10: {=_xlfn.BYROW(B62,_xlfn.LAMBDA(_xlpm.party,SUMIFS(ledger!G:G,ledger!B:B,_xlpm.party,ledger!E:E,"<>*RD*")))+_xlfn.IFNA(C131,0)} -> 1135029 | U10: {=_xlfn.BYROW(B62, _xlfn.LAMBDA(_xlpm.party, SUMIFS(ledger!G:G, ledger!B:B, _xlpm.party, ledger!E:E, "<>*RD*") / 1.0936 ))+_xlfn.IFNA(D131,0)} -> 1037883.1 | V10: {=(_xlfn.BYROW(B62,_xlfn.LAMBDA(_xlpm.party,SUMIFS(ledger!G:G,ledger!B:B,_xlpm.party,ledger!E:E,"<>*RD*",ledger!D:D,"Chamki")+SUMIFS(ledger!G:G, ledger!B:B, _xlpm.party, ledger!E:E, "<>*RD*", ledger!D:D, "Crinkle")))/1.0936)+_xlfn.IFNA(E131,0)} -> 1005535.8 | W10: {=(_xlfn.BYROW(B62,_xlfn.LAMBDA(_xlpm.party,SUMIFS(ledger!G:G,ledger!B:B,_xlpm.party,ledger!E:E,"<>*RD*",ledger!D:D,"Silky")))/1.0936)+_xlfn.IFNA(F131,0)} -> 0 | X10: {=(_xlfn.BYROW(B62,_xlfn.LAMBDA(_xlpm.party, (SUMIFS(ledger!J:J,ledger!B:B,_xlpm.party,ledger!E:E,"<>*RD*",ledger!D:D,"Chamki",ledger!C:C,"<>Closing CF")+ SUMIFS(ledger!J:J,ledger!B:B,_xlpm.party,ledger!E:E,"<>*RD*",ledger!D:D,"Crinkle",ledger!C:C,"<>Closing CF") )+_xlfn.IFNA(G131,0))))} -> 10055358 | Y10: {=_xlfn.BYROW(B62, _xlfn.LAMBDA(_xlpm.party, SUMIFS(ledger!J:J, ledger!B:B, _xlpm.party, ledger!E:E, "<>*RD*", ledger!D:D, "Silky", ledger!C:C, "<>Closing CF") )) + _xlfn.IFNA(H131, 0)} -> 0 | Z10: {=_xlfn.BYROW(B62, _xlfn.LAMBDA(_xlpm.party, SUMIFS(ledger!J:J, ledger!B:B, _xlpm.party, ledger!E:E, "<>*RD*", ledger!D:D, "Slub", ledger!C:C, "<>Closing CF") ))+ _xlfn.IFNA(I131, 0)} -> 71359.729 | AA10: {=_xlfn.BYROW(B62, _xlfn.LAMBDA(_xlpm.party, SUMIFS(ledger!J:J, ledger!B:B, _xlpm.party, ledger!E:E, "<>*RD*", ledger!D:D, "Satin", ledger!C:C, "<>Closing CF") ))+ _xlfn.IFNA(J131, 0)} -> 0 | AB10: {=_xlfn.BYROW(B62, _xlfn.LAMBDA(_xlpm.party, SUMIFS(ledger!J:J, ledger!B:B, _xlpm.party, ledger!E:E, "<>*RD*", ledger!D:D, "Black-Chamki", ledger!C:C, "<>Closing CF") ))+ _xlfn.IFNA(K131, 0)} -> 322297 | AC10: {=_xlfn.BYROW(B62, _xlfn.LAMBDA(_xlpm.party, SUMIFS(ledger!J:J, ledger!B:B, _xlpm.party, ledger!E:E, "<>*RD*", ledger!D:D, "Kataan", ledger!C:C, "<>Closing CF") ))+ _xlfn.IFNA(L131, 0)} -> 0 | AD10: {=_xlfn.BYROW(B62, _xlfn.LAMBDA(_xlpm.party, SUMIFS(ledger!J:J, ledger!B:B, _xlpm.party, ledger!E:E, "<>*RD*", ledger!D:D, "Munaar", ledger!C:C, "<>Closing CF") ))+ _xlfn.IFNA(M131, 0)} -> 0 | AE10: {=_xlfn.BYROW(B62, _xlfn.LAMBDA(_xlpm.party, SUMIFS(ledger!J:J, ledger!B:B, _xlpm.party, ledger!E:E, "<>*RD*", ledger!D:D, "Super Kataan", ledger!C:C, "<>Closing CF") ))+ _xlfn.IFNA(N131, 0)} -> 0 | AF10: {=_xlfn.BYROW(B62, _xlfn.LAMBDA(_xlpm.party, SUMIFS(ledger!J:J, ledger!B:B, _xlpm.party, ledger!E:E, "<>*RD*", ledger!D:D, "Custom", ledger!C:C, "<>Closing CF") ))+ _xlfn.IFNA(O131, 0)} -> 0 | AG10: =X10+Y10+Z10+AA10+AB10+AC10+AD10+AF10+AE10 -> 10449015 | AH10: =(SUMIF(Table14[Party],S10,Table14[Credit]))+_xlfn.IFNA(Q131,0) -> 10448871 | AI10: =AG10-AH10 -> 144.17922 | AJ10: 10 | AK10: 13
B11: =B66 -> Ashraf Zia | C11: =SUMIFS(ledger!G:G, ledger!B:B, B11, ledger!E:E, "<>*RD*") / 1.0936 -> 0 | D11: 12 | E11: =(SUMIFS(ledger!G:G, ledger!B:B, B11, ledger!E:E, "<>*RD*",ledger!D:D, "Silky") / 1.0936)*12 + (SUMIFS(ledger!G:G, ledger!B:B, B11, ledger!E:E, "<>*RD*",ledger!D:D, "Chamki") / 1.0936)*10 -> 0 | I11: Ashraf Zia | S11: Raaz Fabrics | T11: {=_xlfn.BYROW(B63,_xlfn.LAMBDA(_xlpm.party,SUMIFS(ledger!G:G,ledger!B:B,_xlpm.party,ledger!E:E,"<>*RD*")))+_xlfn.IFNA(C132,0)} -> 283694 | U11: {=_xlfn.BYROW(B63, _xlfn.LAMBDA(_xlpm.party, SUMIFS(ledger!G:G, ledger!B:B, _xlpm.party, ledger!E:E, "<>*RD*") / 1.0936 ))+_xlfn.IFNA(D132,0)} -> 259412.95 | V11: {=(_xlfn.BYROW(B63,_xlfn.LAMBDA(_xlpm.party,SUMIFS(ledger!G:G,ledger!B:B,_xlpm.party,ledger!E:E,"<>*RD*",ledger!D:D,"Chamki")+SUMIFS(ledger!G:G, ledger!B:B, _xlpm.party, ledger!E:E, "<>*RD*", ledger!D:D, "Crinkle")))/1.0936)+_xlfn.IFNA(E132,0)} -> 259412.95 | W11: {=(_xlfn.BYROW(B63,_xlfn.LAMBDA(_xlpm.party,SUMIFS(ledger!G:G,ledger!B:B,_xlpm.party,ledger!E:E,"<>*RD*",ledger!D:D,"Silky")))/1.0936)+_xlfn.IFNA(F132,0)} -> 0 | X11: {=(_xlfn.BYROW(B63,_xlfn.LAMBDA(_xlpm.party, (SUMIFS(ledger!J:J,ledger!B:B,_xlpm.party,ledger!E:E,"<>*RD*",ledger!D:D,"Chamki",ledger!C:C,"<>Closing CF")+ SUMIFS(ledger!J:J,ledger!B:B,_xlpm.party,ledger!E:E,"<>*RD*",ledger!D:D,"Crinkle",ledger!C:C,"<>Closing CF") )+_xlfn.IFNA(G132,0))))} -> 2594129.5 | Y11: {=_xlfn.BYROW(B63, _xlfn.LAMBDA(_xlpm.party, SUMIFS(ledger!J:J, ledger!B:B, _xlpm.party, ledger!E:E, "<>*RD*", ledger!D:D, "Silky", ledger!C:C, "<>Closing CF") )) + _xlfn.IFNA(H132, 0)} -> 0 | Z11: {=_xlfn.BYROW(B63, _xlfn.LAMBDA(_xlpm.party, SUMIFS(ledger!J:J, ledger!B:B, _xlpm.party, ledger!E:E, "<>*RD*", ledger!D:D, "Slub", ledger!C:C, "<>Closing CF") ))+ _xlfn.IFNA(I132, 0)} -> 0 | AA11: {=_xlfn.BYROW(B63, _xlfn.LAMBDA(_xlpm.party, SUMIFS(ledger!J:J, ledger!B:B, _xlpm.party, ledger!E:E, "<>*RD*", ledger!D:D, "Satin", ledger!C:C, "<>Closing CF") ))+ _xlfn.IFNA(J132, 0)} -> 0 | AB11: {=_xlfn.BYROW(B63, _xlfn.LAMBDA(_xlpm.party, SUMIFS(ledger!J:J, ledger!B:B, _xlpm.party, ledger!E:E, "<>*RD*", ledger!D:D, "Black-Chamki", ledger!C:C, "<>Closing CF") ))+ _xlfn.IFNA(K132, 0)} -> 0 | AC11: {=_xlfn.BYROW(B63, _xlfn.LAMBDA(_xlpm.party, SUMIFS(ledger!J:J, ledger!B:B, _xlpm.party, ledger!E:E, "<>*RD*", ledger!D:D, "Kataan", ledger!C:C, "<>Closing CF") ))+ _xlfn.IFNA(L132, 0)} -> 0 | AD11: {=_xlfn.BYROW(B63, _xlfn.LAMBDA(_xlpm.party, SUMIFS(ledger!J:J, ledger!B:B, _xlpm.party, ledger!E:E, "<>*RD*", ledger!D:D, "Munaar", ledger!C:C, "<>Closing CF") ))+ _xlfn.IFNA(M132, 0)} -> 0 | AE11: {=_xlfn.BYROW(B63, _xlfn.LAMBDA(_xlpm.party, SUMIFS(ledger!J:J, ledger!B:B, _xlpm.party, ledger!E:E, "<>*RD*", ledger!D:D, "Super Kataan", ledger!C:C, "<>Closing CF") ))+ _xlfn.IFNA(N132, 0)} -> 0 | AF11: {=_xlfn.BYROW(B63, _xlfn.LAMBDA(_xlpm.party, SUMIFS(ledger!J:J, ledger!B:B, _xlpm.party, ledger!E:E, "<>*RD*", ledger!D:D, "Custom", ledger!C:C, "<>Closing CF") ))+ _xlfn.IFNA(O132, 0)} -> 0 | AG11: =X11+Y11+Z11+AA11+AB11+AC11+AD11+AF11+AE11 -> 2594129.5 | AH11: =(SUMIF(Table14[Party],S11,Table14[Credit]))+_xlfn.IFNA(Q132,0) -> 2176321 | AI11: =AG11-AH11 -> 417808.48 | AJ11: 10 | AK11: 13
B12: =B67 -> Hafiz Qureshi | C12: =SUMIFS(ledger!G:G, ledger!B:B, B12, ledger!E:E, "<>*RD*") / 1.0936 -> 157118.69 | E12: =(SUMIFS(ledger!G:G, ledger!B:B, B12, ledger!E:E, "<>*RD*",ledger!D:D, "Silky") / 1.0936)*12 + (SUMIFS(ledger!G:G, ledger!B:B, B12, ledger!E:E, "<>*RD*",ledger!D:D, "Chamki") / 1.0936)*10 -> 1212006.2 | I12: Hafiz Qureshi | S12: Azam | T12: {=_xlfn.BYROW(B64,_xlfn.LAMBDA(_xlpm.party,SUMIFS(ledger!G:G,ledger!B:B,_xlpm.party,ledger!E:E,"<>*RD*")))+_xlfn.IFNA(C133,0)} -> 749236 | U12: {=_xlfn.BYROW(B64, _xlfn.LAMBDA(_xlpm.party, SUMIFS(ledger!G:G, ledger!B:B, _xlpm.party, ledger!E:E, "<>*RD*") / 1.0936 ))+_xlfn.IFNA(D133,0)} -> 685109.73 | V12: {=(_xlfn.BYROW(B64,_xlfn.LAMBDA(_xlpm.party,SUMIFS(ledger!G:G,ledger!B:B,_xlpm.party,ledger!E:E,"<>*RD*",ledger!D:D,"Chamki")+SUMIFS(ledger!G:G, ledger!B:B, _xlpm.party, ledger!E:E, "<>*RD*", ledger!D:D, "Crinkle")))/1.0936)+_xlfn.IFNA(E133,0)} -> 501118.32 | W12: {=(_xlfn.BYROW(B64,_xlfn.LAMBDA(_xlpm.party,SUMIFS(ledger!G:G,ledger!B:B,_xlpm.party,ledger!E:E,"<>*RD*",ledger!D:D,"Silky")))/1.0936)+_xlfn.IFNA(F133,0)} -> 183991.4 | X12: {=(_xlfn.BYROW(B64,_xlfn.LAMBDA(_xlpm.party, (SUMIFS(ledger!J:J,ledger!B:B,_xlpm.party,ledger!E:E,"<>*RD*",ledger!D:D,"Chamki",ledger!C:C,"<>Closing CF")+ SUMIFS(ledger!J:J,ledger!B:B,_xlpm.party,ledger!E:E,"<>*RD*",ledger!D:D,"Crinkle",ledger!C:C,"<>Closing CF") )+_xlfn.IFNA(G133,0))))} -> 5011183.2 | Y12: {=_xlfn.BYROW(B64, _xlfn.LAMBDA(_xlpm.party, SUMIFS(ledger!J:J, ledger!B:B, _xlpm.party, ledger!E:E, "<>*RD*", ledger!D:D, "Silky", ledger!C:C, "<>Closing CF") )) + _xlfn.IFNA(H133, 0)} -> 2391888.3 | Z12: {=_xlfn.BYROW(B64, _xlfn.LAMBDA(_xlpm.party, SUMIFS(ledger!J:J, ledger!B:B, _xlpm.party, ledger!E:E, "<>*RD*", ledger!D:D, "Slub", ledger!C:C, "<>Closing CF") ))+ _xlfn.IFNA(I133, 0)} -> 0 | AA12: {=_xlfn.BYROW(B64, _xlfn.LAMBDA(_xlpm.party, SUMIFS(ledger!J:J, ledger!B:B, _xlpm.party, ledger!E:E, "<>*RD*", ledger!D:D, "Satin", ledger!C:C, "<>Closing CF") ))+ _xlfn.IFNA(J133, 0)} -> 0 | AB12: {=_xlfn.BYROW(B64, _xlfn.LAMBDA(_xlpm.party, SUMIFS(ledger!J:J, ledger!B:B, _xlpm.party, ledger!E:E, "<>*RD*", ledger!D:D, "Black-Chamki", ledger!C:C, "<>Closing CF") ))+ _xlfn.IFNA(K133, 0)} -> 0 | AC12: {=_xlfn.BYROW(B64, _xlfn.LAMBDA(_xlpm.party, SUMIFS(ledger!J:J, ledger!B:B, _xlpm.party, ledger!E:E, "<>*RD*", ledger!D:D, "Kataan", ledger!C:C, "<>Closing CF") ))+ _xlfn.IFNA(L133, 0)} -> 0 | AD12: {=_xlfn.BYROW(B64, _xlfn.LAMBDA(_xlpm.party, SUMIFS(ledger!J:J, ledger!B:B, _xlpm.party, ledger!E:E, "<>*RD*", ledger!D:D, "Munaar", ledger!C:C, "<>Closing CF") ))+ _xlfn.IFNA(M133, 0)} -> 0 | AE12: {=_xlfn.BYROW(B64, _xlfn.LAMBDA(_xlpm.party, SUMIFS(ledger!J:J, ledger!B:B, _xlpm.party, ledger!E:E, "<>*RD*", ledger!D:D, "Super Kataan", ledger!C:C, "<>Closing CF") ))+ _xlfn.IFNA(N133, 0)} -> 0 | AF12: {=_xlfn.BYROW(B64, _xlfn.LAMBDA(_xlpm.party, SUMIFS(ledger!J:J, ledger!B:B, _xlpm.party, ledger!E:E, "<>*RD*", ledger!D:D, "Custom", ledger!C:C, "<>Closing CF") ))+ _xlfn.IFNA(O133, 0)} -> 0 | AG12: =X12+Y12+Z12+AA12+AB12+AC12+AD12+AF12+AE12 -> 7403071.5 | AH12: =(SUMIF(Table14[Party],S12,Table14[Credit]))+_xlfn.IFNA(Q133,0) -> 7402540 | AI12: =AG12-AH12 -> 531.50695 | AJ12: 10 | AK12: 13
B13: =B68 -> Badshah Fabrics | C13: =SUMIFS(ledger!G:G, ledger!B:B, B13, ledger!E:E, "<>*RD*") / 1.0936 -> 0 | E13: =(SUMIFS(ledger!G:G, ledger!B:B, B13, ledger!E:E, "<>*RD*",ledger!D:D, "Silky") / 1.0936)*12 + (SUMIFS(ledger!G:G, ledger!B:B, B13, ledger!E:E, "<>*RD*",ledger!D:D, "Chamki") / 1.0936)*10 -> 0 | I13: Badshah Fabrics | S13: Ubaidullah | T13: {=_xlfn.BYROW(B65,_xlfn.LAMBDA(_xlpm.party,SUMIFS(ledger!G:G,ledger!B:B,_xlpm.party,ledger!E:E,"<>*RD*")))+_xlfn.IFNA(C134,0)} -> 336741 | U13: {=_xlfn.BYROW(B65, _xlfn.LAMBDA(_xlpm.party, SUMIFS(ledger!G:G, ledger!B:B, _xlpm.party, ledger!E:E, "<>*RD*") / 1.0936 ))+_xlfn.IFNA(D134,0)} -> 307919.71 | V13: {=(_xlfn.BYROW(B65,_xlfn.LAMBDA(_xlpm.party,SUMIFS(ledger!G:G,ledger!B:B,_xlpm.party,ledger!E:E,"<>*RD*",ledger!D:D,"Chamki")+SUMIFS(ledger!G:G, ledger!B:B, _xlpm.party, ledger!E:E, "<>*RD*", ledger!D:D, "Crinkle")))/1.0936)+_xlfn.IFNA(E134,0)} -> 46132.955 | W13: {=(_xlfn.BYROW(B65,_xlfn.LAMBDA(_xlpm.party,SUMIFS(ledger!G:G,ledger!B:B,_xlpm.party,ledger!E:E,"<>*RD*",ledger!D:D,"Silky")))/1.0936)+_xlfn.IFNA(F134,0)} -> 261786.76 | X13: {=(_xlfn.BYROW(B65,_xlfn.LAMBDA(_xlpm.party, (SUMIFS(ledger!J:J,ledger!B:B,_xlpm.party,ledger!E:E,"<>*RD*",ledger!D:D,"Chamki",ledger!C:C,"<>Closing CF")+ SUMIFS(ledger!J:J,ledger!B:B,_xlpm.party,ledger!E:E,"<>*RD*",ledger!D:D,"Crinkle",ledger!C:C,"<>Closing CF") )+_xlfn.IFNA(G134,0))))} -> 461329.55 | Y13: {=_xlfn.BYROW(B65, _xlfn.LAMBDA(_xlpm.party, SUMIFS(ledger!J:J, ledger!B:B, _xlpm.party, ledger!E:E, "<>*RD*", ledger!D:D, "Silky", ledger!C:C, "<>Closing CF") )) + _xlfn.IFNA(H134, 0)} -> 3189934.2 | Z13: {=_xlfn.BYROW(B65, _xlfn.LAMBDA(_xlpm.party, SUMIFS(ledger!J:J, ledger!B:B, _xlpm.party, ledger!E:E, "<>*RD*", ledger!D:D, "Slub", ledger!C:C, "<>Closing CF") ))+ _xlfn.IFNA(I134, 0)} -> 0 | AA13: {=_xlfn.BYROW(B65, _xlfn.LAMBDA(_xlpm.party, SUMIFS(ledger!J:J, ledger!B:B, _xlpm.party, ledger!E:E, "<>*RD*", ledger!D:D, "Satin", ledger!C:C, "<>Closing CF") ))+ _xlfn.IFNA(J134, 0)} -> 0 | AB13: {=_xlfn.BYROW(B65, _xlfn.LAMBDA(_xlpm.party, SUMIFS(ledger!J:J, ledger!B:B, _xlpm.party, ledger!E:E, "<>*RD*", ledger!D:D, "Black-Chamki", ledger!C:C, "<>Closing CF") ))+ _xlfn.IFNA(K134, 0)} -> 0 | AC13: {=_xlfn.BYROW(B65, _xlfn.LAMBDA(_xlpm.party, SUMIFS(ledger!J:J, ledger!B:B, _xlpm.party, ledger!E:E, "<>*RD*", ledger!D:D, "Kataan", ledger!C:C, "<>Closing CF") ))+ _xlfn.IFNA(L134, 0)} -> 0 | AD13: {=_xlfn.BYROW(B65, _xlfn.LAMBDA(_xlpm.party, SUMIFS(ledger!J:J, ledger!B:B, _xlpm.party, ledger!E:E, "<>*RD*", ledger!D:D, "Munaar", ledger!C:C, "<>Closing CF") ))+ _xlfn.IFNA(M134, 0)} -> 0 | AE13: {=_xlfn.BYROW(B65, _xlfn.LAMBDA(_xlpm.party, SUMIFS(ledger!J:J, ledger!B:B, _xlpm.party, ledger!E:E, "<>*RD*", ledger!D:D, "Super Kataan", ledger!C:C, "<>Closing CF") ))+ _xlfn.IFNA(N134, 0)} -> 0 | AF13: {=_xlfn.BYROW(B65, _xlfn.LAMBDA(_xlpm.party, SUMIFS(ledger!J:J, ledger!B:B, _xlpm.party, ledger!E:E, "<>*RD*", ledger!D:D, "Custom", ledger!C:C, "<>Closing CF") ))+ _xlfn.IFNA(O134, 0)} -> 0 | AG13: =X13+Y13+Z13+AA13+AB13+AC13+AD13+AF13+AE13 -> 3651263.7 | AH13: =(SUMIF(Table14[Party],S13,Table14[Credit]))+_xlfn.IFNA(Q134,0) -> 3649649 | AI13: =AG13-AH13 -> 1614.7162 | AJ13: 10 | AK13: 13
B14: =B69 -> Gauhar Kashif | C14: =SUMIFS(ledger!G:G, ledger!B:B, B14, ledger!E:E, "<>*RD*") / 1.0936 -> 0 | E14: =(SUMIFS(ledger!G:G, ledger!B:B, B14, ledger!E:E, "<>*RD*",ledger!D:D, "Silky") / 1.0936)*12 + (SUMIFS(ledger!G:G, ledger!B:B, B14, ledger!E:E, "<>*RD*",ledger!D:D, "Chamki") / 1.0936)*10 -> 0 | I14: Reject | S14: Ashraf Zia | T14: {=_xlfn.BYROW(B66,_xlfn.LAMBDA(_xlpm.party,SUMIFS(ledger!G:G,ledger!B:B,_xlpm.party,ledger!E:E,"<>*RD*")))+_xlfn.IFNA(C135,0)} -> 23305 | U14: {=_xlfn.BYROW(B66, _xlfn.LAMBDA(_xlpm.party, SUMIFS(ledger!G:G, ledger!B:B, _xlpm.party, ledger!E:E, "<>*RD*") / 1.0936 ))+_xlfn.IFNA(D135,0)} -> 21310.351 | V14: {=(_xlfn.BYROW(B66,_xlfn.LAMBDA(_xlpm.party,SUMIFS(ledger!G:G,ledger!B:B,_xlpm.party,ledger!E:E,"<>*RD*",ledger!D:D,"Chamki")+SUMIFS(ledger!G:G, ledger!B:B, _xlpm.party, ledger!E:E, "<>*RD*", ledger!D:D, "Crinkle")))/1.0936)+_xlfn.IFNA(E135,0)} -> 21310.351 | W14: {=(_xlfn.BYROW(B66,_xlfn.LAMBDA(_xlpm.party,SUMIFS(ledger!G:G,ledger!B:B,_xlpm.party,ledger!E:E,"<>*RD*",ledger!D:D,"Silky")))/1.0936)+_xlfn.IFNA(F135,0)} -> 0 | X14: {=(_xlfn.BYROW(B66,_xlfn.LAMBDA(_xlpm.party, (SUMIFS(ledger!J:J,ledger!B:B,_xlpm.party,ledger!E:E,"<>*RD*",ledger!D:D,"Chamki",ledger!C:C,"<>Closing CF")+ SUMIFS(ledger!J:J,ledger!B:B,_xlpm.party,ledger!E:E,"<>*RD*",ledger!D:D,"Crinkle",ledger!C:C,"<>Closing CF") )+_xlfn.IFNA(G135,0))))} -> 255724.21 | Y14: {=_xlfn.BYROW(B66, _xlfn.LAMBDA(_xlpm.party, SUMIFS(ledger!J:J, ledger!B:B, _xlpm.party, ledger!E:E, "<>*RD*", ledger!D:D, "Silky", ledger!C:C, "<>Closing CF") )) + _xlfn.IFNA(H135, 0)} -> 0 | Z14: {=_xlfn.BYROW(B66, _xlfn.LAMBDA(_xlpm.party, SUMIFS(ledger!J:J, ledger!B:B, _xlpm.party, ledger!E:E, "<>*RD*", ledger!D:D, "Slub", ledger!C:C, "<>Closing CF") ))+ _xlfn.IFNA(I135, 0)} -> 0 | AA14: {=_xlfn.BYROW(B66, _xlfn.LAMBDA(_xlpm.party, SUMIFS(ledger!J:J, ledger!B:B, _xlpm.party, ledger!E:E, "<>*RD*", ledger!D:D, "Satin", ledger!C:C, "<>Closing CF") ))+ _xlfn.IFNA(J135, 0)} -> 0 | AB14: {=_xlfn.BYROW(B66, _xlfn.LAMBDA(_xlpm.party, SUMIFS(ledger!J:J, ledger!B:B, _xlpm.party, ledger!E:E, "<>*RD*", ledger!D:D, "Black-Chamki", ledger!C:C, "<>Closing CF") ))+ _xlfn.IFNA(K135, 0)} -> 0 | AC14: {=_xlfn.BYROW(B66, _xlfn.LAMBDA(_xlpm.party, SUMIFS(ledger!J:J, ledger!B:B, _xlpm.party, ledger!E:E, "<>*RD*", ledger!D:D, "Kataan", ledger!C:C, "<>Closing CF") ))+ _xlfn.IFNA(L135, 0)} -> 0 | AD14: {=_xlfn.BYROW(B66, _xlfn.LAMBDA(_xlpm.party, SUMIFS(ledger!J:J, ledger!B:B, _xlpm.party, ledger!E:E, "<>*RD*", ledger!D:D, "Munaar", ledger!C:C, "<>Closing CF") ))+ _xlfn.IFNA(M135, 0)} -> 0 | AE14: {=_xlfn.BYROW(B66, _xlfn.LAMBDA(_xlpm.party, SUMIFS(ledger!J:J, ledger!B:B, _xlpm.party, ledger!E:E, "<>*RD*", ledger!D:D, "Super Kataan", ledger!C:C, "<>Closing CF") ))+ _xlfn.IFNA(N135, 0)} -> 0 | AF14: {=_xlfn.BYROW(B66, _xlfn.LAMBDA(_xlpm.party, SUMIFS(ledger!J:J, ledger!B:B, _xlpm.party, ledger!E:E, "<>*RD*", ledger!D:D, "Custom", ledger!C:C, "<>Closing CF") ))+ _xlfn.IFNA(O135, 0)} -> 0 | AG14: =X14+Y14+Z14+AA14+AB14+AC14+AD14+AF14+AE14 -> 255724.21 | AH14: =(SUMIF(Table14[Party],S14,Table14[Credit]))+_xlfn.IFNA(Q135,0) -> 130000 | AI14: =AG14-AH14 -> 125724.21 | AJ14: 12 | AK14: 13
B15: =B70 -> Amjad 7up | C15: =SUMIFS(ledger!G:G, ledger!B:B, B15, ledger!E:E, "<>*RD*") / 1.0936 -> 0 | E15: =(SUMIFS(ledger!G:G, ledger!B:B, B15, ledger!E:E, "<>*RD*",ledger!D:D, "Silky") / 1.0936)*12 + (SUMIFS(ledger!G:G, ledger!B:B, B15, ledger!E:E, "<>*RD*",ledger!D:D, "Chamki") / 1.0936)*10 -> 0 | I15: Amjad 7up | S15: Hafiz Qureshi | T15: {=_xlfn.BYROW(B67,_xlfn.LAMBDA(_xlpm.party,SUMIFS(ledger!G:G,ledger!B:B,_xlpm.party,ledger!E:E,"<>*RD*")))+_xlfn.IFNA(C136,0)} -> 809806 | U15: {=_xlfn.BYROW(B67, _xlfn.LAMBDA(_xlpm.party, SUMIFS(ledger!G:G, ledger!B:B, _xlpm.party, ledger!E:E, "<>*RD*") / 1.0936 ))+_xlfn.IFNA(D136,0)} -> 740495.61 | V15: {=(_xlfn.BYROW(B67,_xlfn.LAMBDA(_xlpm.party,SUMIFS(ledger!G:G,ledger!B:B,_xlpm.party,ledger!E:E,"<>*RD*",ledger!D:D,"Chamki")+SUMIFS(ledger!G:G, ledger!B:B, _xlpm.party, ledger!E:E, "<>*RD*", ledger!D:D, "Crinkle")))/1.0936)+_xlfn.IFNA(E136,0)} -> 635991.22 | W15: {=(_xlfn.BYROW(B67,_xlfn.LAMBDA(_xlpm.party,SUMIFS(ledger!G:G,ledger!B:B,_xlpm.party,ledger!E:E,"<>*RD*",ledger!D:D,"Silky")))/1.0936)+_xlfn.IFNA(F136,0)} -> 57155.267 | X15: {=(_xlfn.BYROW(B67,_xlfn.LAMBDA(_xlpm.party, (SUMIFS(ledger!J:J,ledger!B:B,_xlpm.party,ledger!E:E,"<>*RD*",ledger!D:D,"Chamki",ledger!C:C,"<>Closing CF")+ SUMIFS(ledger!J:J,ledger!B:B,_xlpm.party,ledger!E:E,"<>*RD*",ledger!D:D,"Crinkle",ledger!C:C,"<>Closing CF") )+_xlfn.IFNA(G136,0))))} -> 6359912.2 | Y15: {=_xlfn.BYROW(B67, _xlfn.LAMBDA(_xlpm.party, SUMIFS(ledger!J:J, ledger!B:B, _xlpm.party, ledger!E:E, "<>*RD*", ledger!D:D, "Silky", ledger!C:C, "<>Closing CF") )) + _xlfn.IFNA(H136, 0)} -> 743018.47 | Z15: {=_xlfn.BYROW(B67, _xlfn.LAMBDA(_xlpm.party, SUMIFS(ledger!J:J, ledger!B:B, _xlpm.party, ledger!E:E, "<>*RD*", ledger!D:D, "Slub", ledger!C:C, "<>Closing CF") ))+ _xlfn.IFNA(I136, 0)} -> 0 | AA15: {=_xlfn.BYROW(B67, _xlfn.LAMBDA(_xlpm.party, SUMIFS(ledger!J:J, ledger!B:B, _xlpm.party, ledger!E:E, "<>*RD*", ledger!D:D, "Satin", ledger!C:C, "<>Closing CF") ))+ _xlfn.IFNA(J136, 0)} -> 0 | AB15: {=_xlfn.BYROW(B67, _xlfn.LAMBDA(_xlpm.party, SUMIFS(ledger!J:J, ledger!B:B, _xlpm.party, ledger!E:E, "<>*RD*", ledger!D:D, "Black-Chamki", ledger!C:C, "<>Closing CF") ))+ _xlfn.IFNA(K136, 0)} -> 0 | AC15: {=_xlfn.BYROW(B67, _xlfn.LAMBDA(_xlpm.party, SUMIFS(ledger!J:J, ledger!B:B, _xlpm.party, ledger!E:E, "<>*RD*", ledger!D:D, "Kataan", ledger!C:C, "<>Closing CF") ))+ _xlfn.IFNA(L136, 0)} -> 520840.34 | AD15: {=_xlfn.BYROW(B67, _xlfn.LAMBDA(_xlpm.party, SUMIFS(ledger!J:J, ledger!B:B, _xlpm.party, ledger!E:E, "<>*RD*", ledger!D:D, "Munaar", ledger!C:C, "<>Closing CF") ))+ _xlfn.IFNA(M136, 0)} -> 0 | AE15: {=_xlfn.BYROW(B67, _xlfn.LAMBDA(_xlpm.party, SUMIFS(ledger!J:J, ledger!B:B, _xlpm.party, ledger!E:E, "<>*RD*", ledger!D:D, "Super Kataan", ledger!C:C, "<>Closing CF") ))+ _xlfn.IFNA(N136, 0)} -> 0 | AF15: {=_xlfn.BYROW(B67, _xlfn.LAMBDA(_xlpm.party, SUMIFS(ledger!J:J, ledger!B:B, _xlpm.party, ledger!E:E, "<>*RD*", ledger!D:D, "Custom", ledger!C:C, "<>Closing CF") ))+ _xlfn.IFNA(O136, 0)} -> 0 | AG15: =X15+Y15+Z15+AA15+AB15+AC15+AD15+AF15+AE15 -> 7623771 | AH15: =(SUMIF(Table14[Party],S15,Table14[Credit]))+_xlfn.IFNA(Q136,0) -> 6835303 | AI15: =AG15-AH15 -> 788468.03 | AJ15: 10 | AK15: 13
B16: =B71 -> Hazrat Khan | C16: =SUMIFS(ledger!G:G, ledger!B:B, B16, ledger!E:E, "<>*RD*") / 1.0936 -> 0 | E16: =(SUMIFS(ledger!G:G, ledger!B:B, B16, ledger!E:E, "<>*RD*",ledger!D:D, "Silky") / 1.0936)*12 + (SUMIFS(ledger!G:G, ledger!B:B, B16, ledger!E:E, "<>*RD*",ledger!D:D, "Chamki") / 1.0936)*10 -> 0 | I16: Hazrat Khan | S16: Badshah Fabrics | T16: {=_xlfn.BYROW(B68,_xlfn.LAMBDA(_xlpm.party,SUMIFS(ledger!G:G,ledger!B:B,_xlpm.party,ledger!E:E,"<>*RD*")))+_xlfn.IFNA(C137,0)} -> 681314 | U16: {=_xlfn.BYROW(B68, _xlfn.LAMBDA(_xlpm.party, SUMIFS(ledger!G:G, ledger!B:B, _xlpm.party, ledger!E:E, "<>*RD*") / 1.0936 ))+_xlfn.IFNA(D137,0)} -> 623001.1 | V16: {=(_xlfn.BYROW(B68,_xlfn.LAMBDA(_xlpm.party,SUMIFS(ledger!G:G,ledger!B:B,_xlpm.party,ledger!E:E,"<>*RD*",ledger!D:D,"Chamki")+SUMIFS(ledger!G:G, ledger!B:B, _xlpm.party, ledger!E:E, "<>*RD*", ledger!D:D, "Crinkle")))/1.0936)+_xlfn.IFNA(E137,0)} -> 481526.15 | W16: {=(_xlfn.BYROW(B68,_xlfn.LAMBDA(_xlpm.party,SUMIFS(ledger!G:G,ledger!B:B,_xlpm.party,ledger!E:E,"<>*RD*",ledger!D:D,"Silky")))/1.0936)+_xlfn.IFNA(F137,0)} -> 141474.95 | X16: {=(_xlfn.BYROW(B68,_xlfn.LAMBDA(_xlpm.party, (SUMIFS(ledger!J:J,ledger!B:B,_xlpm.party,ledger!E:E,"<>*RD*",ledger!D:D,"Chamki",ledger!C:C,"<>Closing CF")+ SUMIFS(ledger!J:J,ledger!B:B,_xlpm.party,ledger!E:E,"<>*RD*",ledger!D:D,"Crinkle",ledger!C:C,"<>Closing CF") )+_xlfn.IFNA(G137,0))))} -> 4861679.8 | Y16: {=_xlfn.BYROW(B68, _xlfn.LAMBDA(_xlpm.party, SUMIFS(ledger!J:J, ledger!B:B, _xlpm.party, ledger!E:E, "<>*RD*", ledger!D:D, "Silky", ledger!C:C, "<>Closing CF") )) + _xlfn.IFNA(H137, 0)} -> 1776019.6 | Z16: {=_xlfn.BYROW(B68, _xlfn.LAMBDA(_xlpm.party, SUMIFS(ledger!J:J, ledger!B:B, _xlpm.party, ledger!E:E, "<>*RD*", ledger!D:D, "Slub", ledger!C:C, "<>Closing CF") ))+ _xlfn.IFNA(I137, 0)} -> 0 | AA16: {=_xlfn.BYROW(B68, _xlfn.LAMBDA(_xlpm.party, SUMIFS(ledger!J:J, ledger!B:B, _xlpm.party, ledger!E:E, "<>*RD*", ledger!D:D, "Satin", ledger!C:C, "<>Closing CF") ))+ _xlfn.IFNA(J137, 0)} -> 0 | AB16: {=_xlfn.BYROW(B68, _xlfn.LAMBDA(_xlpm.party, SUMIFS(ledger!J:J, ledger!B:B, _xlpm.party, ledger!E:E, "<>*RD*", ledger!D:D, "Black-Chamki", ledger!C:C, "<>Closing CF") ))+ _xlfn.IFNA(K137, 0)} -> 0 | AC16: {=_xlfn.BYROW(B68, _xlfn.LAMBDA(_xlpm.party, SUMIFS(ledger!J:J, ledger!B:B, _xlpm.party, ledger!E:E, "<>*RD*", ledger!D:D, "Kataan", ledger!C:C, "<>Closing CF") ))+ _xlfn.IFNA(L137, 0)} -> 0 | AD16: {=_xlfn.BYROW(B68, _xlfn.LAMBDA(_xlpm.party, SUMIFS(ledger!J:J, ledger!B:B, _xlpm.party, ledger!E:E, "<>*RD*", ledger!D:D, "Munaar", ledger!C:C, "<>Closing CF") ))+ _xlfn.IFNA(M137, 0)} -> 0 | AE16: {=_xlfn.BYROW(B68, _xlfn.LAMBDA(_xlpm.party, SUMIFS(ledger!J:J, ledger!B:B, _xlpm.party, ledger!E:E, "<>*RD*", ledger!D:D, "Super Kataan", ledger!C:C, "<>Closing CF") ))+ _xlfn.IFNA(N137, 0)} -> 0 | AF16: {=_xlfn.BYROW(B68, _xlfn.LAMBDA(_xlpm.party, SUMIFS(ledger!J:J, ledger!B:B, _xlpm.party, ledger!E:E, "<>*RD*", ledger!D:D, "Custom", ledger!C:C, "<>Closing CF") ))+ _xlfn.IFNA(O137, 0)} -> 0 | AG16: =X16+Y16+Z16+AA16+AB16+AC16+AD16+AF16+AE16 -> 6637699.3 | AH16: =(SUMIF(Table14[Party],S16,Table14[Credit]))+_xlfn.IFNA(Q137,0) -> 6545761 | AI16: =AG16-AH16 -> 91938.342 | AJ16: 10 | AK16: 13
B17: =B72 -> Haseeb Shamsi | C17: =SUMIFS(ledger!G:G, ledger!B:B, B17, ledger!E:E, "<>*RD*") / 1.0936 -> 0 | E17: =(SUMIFS(ledger!G:G, ledger!B:B, B17, ledger!E:E, "<>*RD*",ledger!D:D, "Silky") / 1.0936)*12 + (SUMIFS(ledger!G:G, ledger!B:B, B17, ledger!E:E, "<>*RD*",ledger!D:D, "Chamki") / 1.0936)*10 -> 0 | I17: Haseeb Shamsi | S17: Gauhar Kashif | T17: {=_xlfn.BYROW(B69,_xlfn.LAMBDA(_xlpm.party,SUMIFS(ledger!G:G,ledger!B:B,_xlpm.party,ledger!E:E,"<>*RD*")))+_xlfn.IFNA(C138,0)} -> 132768 | U17: {=_xlfn.BYROW(B69, _xlfn.LAMBDA(_xlpm.party, SUMIFS(ledger!G:G, ledger!B:B, _xlpm.party, ledger!E:E, "<>*RD*") / 1.0936 ))+_xlfn.IFNA(D138,0)} -> 121404.54 | V17: {=(_xlfn.BYROW(B69,_xlfn.LAMBDA(_xlpm.party,SUMIFS(ledger!G:G,ledger!B:B,_xlpm.party,ledger!E:E,"<>*RD*",ledger!D:D,"Chamki")+SUMIFS(ledger!G:G, ledger!B:B, _xlpm.party, ledger!E:E, "<>*RD*", ledger!D:D, "Crinkle")))/1.0936)+_xlfn.IFNA(E138,0)} -> 121404.54 | W17: {=(_xlfn.BYROW(B69,_xlfn.LAMBDA(_xlpm.party,SUMIFS(ledger!G:G,ledger!B:B,_xlpm.party,ledger!E:E,"<>*RD*",ledger!D:D,"Silky")))/1.0936)+_xlfn.IFNA(F138,0)} -> 0 | X17: {=(_xlfn.BYROW(B69,_xlfn.LAMBDA(_xlpm.party, (SUMIFS(ledger!J:J,ledger!B:B,_xlpm.party,ledger!E:E,"<>*RD*",ledger!D:D,"Chamki",ledger!C:C,"<>Closing CF")+ SUMIFS(ledger!J:J,ledger!B:B,_xlpm.party,ledger!E:E,"<>*RD*",ledger!D:D,"Crinkle",ledger!C:C,"<>Closing CF") )+_xlfn.IFNA(G138,0))))} -> 1214045.4 | Y17: {=_xlfn.BYROW(B69, _xlfn.LAMBDA(_xlpm.party, SUMIFS(ledger!J:J, ledger!B:B, _xlpm.party, ledger!E:E, "<>*RD*", ledger!D:D, "Silky", ledger!C:C, "<>Closing CF") )) + _xlfn.IFNA(H138, 0)} -> 0 | Z17: {=_xlfn.BYROW(B69, _xlfn.LAMBDA(_xlpm.party, SUMIFS(ledger!J:J, ledger!B:B, _xlpm.party, ledger!E:E, "<>*RD*", ledger!D:D, "Slub", ledger!C:C, "<>Closing CF") ))+ _xlfn.IFNA(I138, 0)} -> 0 | AA17: {=_xlfn.BYROW(B69, _xlfn.LAMBDA(_xlpm.party, SUMIFS(ledger!J:J, ledger!B:B, _xlpm.party, ledger!E:E, "<>*RD*", ledger!D:D, "Satin", ledger!C:C, "<>Closing CF") ))+ _xlfn.IFNA(J138, 0)} -> 0 | AB17: {=_xlfn.BYROW(B69, _xlfn.LAMBDA(_xlpm.party, SUMIFS(ledger!J:J, ledger!B:B, _xlpm.party, ledger!E:E, "<>*RD*", ledger!D:D, "Black-Chamki", ledger!C:C, "<>Closing CF") ))+ _xlfn.IFNA(K138, 0)} -> 0 | AC17: {=_xlfn.BYROW(B69, _xlfn.LAMBDA(_xlpm.party, SUMIFS(ledger!J:J, ledger!B:B, _xlpm.party, ledger!E:E, "<>*RD*", ledger!D:D, "Kataan", ledger!C:C, "<>Closing CF") ))+ _xlfn.IFNA(L138, 0)} -> 0 | AD17: {=_xlfn.BYROW(B69, _xlfn.LAMBDA(_xlpm.party, SUMIFS(ledger!J:J, ledger!B:B, _xlpm.party, ledger!E:E, "<>*RD*", ledger!D:D, "Munaar", ledger!C:C, "<>Closing CF") ))+ _xlfn.IFNA(M138, 0)} -> 0 | AE17: {=_xlfn.BYROW(B69, _xlfn.LAMBDA(_xlpm.party, SUMIFS(ledger!J:J, ledger!B:B, _xlpm.party, ledger!E:E, "<>*RD*", ledger!D:D, "Super Kataan", ledger!C:C, "<>Closing CF") ))+ _xlfn.IFNA(N138, 0)} -> 0 | AF17: {=_xlfn.BYROW(B69, _xlfn.LAMBDA(_xlpm.party, SUMIFS(ledger!J:J, ledger!B:B, _xlpm.party, ledger!E:E, "<>*RD*", ledger!D:D, "Custom", ledger!C:C, "<>Closing CF") ))+ _xlfn.IFNA(O138, 0)} -> 0 | AG17: =X17+Y17+Z17+AA17+AB17+AC17+AD17+AF17+AE17 -> 1214045.4 | AH17: =(SUMIF(Table14[Party],S17,Table14[Credit]))+_xlfn.IFNA(Q138,0) -> 1214045 | AI17: =AG17-AH17 -> 0.35479151 | AJ17: 10 | AK17: 13
B18: =B73 -> Faizan | C18: =SUMIFS(ledger!G:G, ledger!B:B, B18, ledger!E:E, "<>*RD*") / 1.0936 -> 0 | E18: =(SUMIFS(ledger!G:G, ledger!B:B, B18, ledger!E:E, "<>*RD*",ledger!D:D, "Silky") / 1.0936)*12 + (SUMIFS(ledger!G:G, ledger!B:B, B18, ledger!E:E, "<>*RD*",ledger!D:D, "Chamki") / 1.0936)*10 -> 0 | I18: Faizan | S18: Amjad 7up | T18: {=_xlfn.BYROW(B70,_xlfn.LAMBDA(_xlpm.party,SUMIFS(ledger!G:G,ledger!B:B,_xlpm.party,ledger!E:E,"<>*RD*")))+_xlfn.IFNA(C139,0)} -> 52914 | U18: {=_xlfn.BYROW(B70, _xlfn.LAMBDA(_xlpm.party, SUMIFS(ledger!G:G, ledger!B:B, _xlpm.party, ledger!E:E, "<>*RD*") / 1.0936 ))+_xlfn.IFNA(D139,0)} -> 48385.15 | V18: {=(_xlfn.BYROW(B70,_xlfn.LAMBDA(_xlpm.party,SUMIFS(ledger!G:G,ledger!B:B,_xlpm.party,ledger!E:E,"<>*RD*",ledger!D:D,"Chamki")+SUMIFS(ledger!G:G, ledger!B:B, _xlpm.party, ledger!E:E, "<>*RD*", ledger!D:D, "Crinkle")))/1.0936)+_xlfn.IFNA(E139,0)} -> 48385.15 | W18: {=(_xlfn.BYROW(B70,_xlfn.LAMBDA(_xlpm.party,SUMIFS(ledger!G:G,ledger!B:B,_xlpm.party,ledger!E:E,"<>*RD*",ledger!D:D,"Silky")))/1.0936)+_xlfn.IFNA(F139,0)} -> 0 | X18: {=(_xlfn.BYROW(B70,_xlfn.LAMBDA(_xlpm.party, (SUMIFS(ledger!J:J,ledger!B:B,_xlpm.party,ledger!E:E,"<>*RD*",ledger!D:D,"Chamki",ledger!C:C,"<>Closing CF")+ SUMIFS(ledger!J:J,ledger!B:B,_xlpm.party,ledger!E:E,"<>*RD*",ledger!D:D,"Crinkle",ledger!C:C,"<>Closing CF") )+_xlfn.IFNA(G139,0))))} -> 483851.5 | Y18: {=_xlfn.BYROW(B70, _xlfn.LAMBDA(_xlpm.party, SUMIFS(ledger!J:J, ledger!B:B, _xlpm.party, ledger!E:E, "<>*RD*", ledger!D:D, "Silky", ledger!C:C, "<>Closing CF") )) + _xlfn.IFNA(H139, 0)} -> 0 | Z18: {=_xlfn.BYROW(B70, _xlfn.LAMBDA(_xlpm.party, SUMIFS(ledger!J:J, ledger!B:B, _xlpm.party, ledger!E:E, "<>*RD*", ledger!D:D, "Slub", ledger!C:C, "<>Closing CF") ))+ _xlfn.IFNA(I139, 0)} -> 0 | AA18: {=_xlfn.BYROW(B70, _xlfn.LAMBDA(_xlpm.party, SUMIFS(ledger!J:J, ledger!B:B, _xlpm.party, ledger!E:E, "<>*RD*", ledger!D:D, "Satin", ledger!C:C, "<>Closing CF") ))+ _xlfn.IFNA(J139, 0)} -> 0 | AB18: {=_xlfn.BYROW(B70, _xlfn.LAMBDA(_xlpm.party, SUMIFS(ledger!J:J, ledger!B:B, _xlpm.party, ledger!E:E, "<>*RD*", ledger!D:D, "Black-Chamki", ledger!C:C, "<>Closing CF") ))+ _xlfn.IFNA(K139, 0)} -> 0 | AC18: {=_xlfn.BYROW(B70, _xlfn.LAMBDA(_xlpm.party, SUMIFS(ledger!J:J, ledger!B:B, _xlpm.party, ledger!E:E, "<>*RD*", ledger!D:D, "Kataan", ledger!C:C, "<>Closing CF") ))+ _xlfn.IFNA(L139, 0)} -> 0 | AD18: {=_xlfn.BYROW(B70, _xlfn.LAMBDA(_xlpm.party, SUMIFS(ledger!J:J, ledger!B:B, _xlpm.party, ledger!E:E, "<>*RD*", ledger!D:D, "Munaar", ledger!C:C, "<>Closing CF") ))+ _xlfn.IFNA(M139, 0)} -> 0 | AE18: {=_xlfn.BYROW(B70, _xlfn.LAMBDA(_xlpm.party, SUMIFS(ledger!J:J, ledger!B:B, _xlpm.party, ledger!E:E, "<>*RD*", ledger!D:D, "Super Kataan", ledger!C:C, "<>Closing CF") ))+ _xlfn.IFNA(N139, 0)} -> 0 | AF18: {=_xlfn.BYROW(B70, _xlfn.LAMBDA(_xlpm.party, SUMIFS(ledger!J:J, ledger!B:B, _xlpm.party, ledger!E:E, "<>*RD*", ledger!D:D, "Custom", ledger!C:C, "<>Closing CF") ))+ _xlfn.IFNA(O139, 0)} -> 0 | AG18: =X18+Y18+Z18+AA18+AB18+AC18+AD18+AF18+AE18 -> 483851.5 | AH18: =(SUMIF(Table14[Party],S18,Table14[Credit]))+_xlfn.IFNA(Q139,0) -> 480000 | AI18: =AG18-AH18 -> 3851.4996 | AJ18: 10 | AK18: 13
I19: Shafique Ansari | S19: Hazrat Khan | T19: {=_xlfn.BYROW(B71,_xlfn.LAMBDA(_xlpm.party,SUMIFS(ledger!G:G,ledger!B:B,_xlpm.party,ledger!E:E,"<>*RD*")))+_xlfn.IFNA(C140,0)} -> 9750 | U19: {=_xlfn.BYROW(B71, _xlfn.LAMBDA(_xlpm.party, SUMIFS(ledger!G:G, ledger!B:B, _xlpm.party, ledger!E:E, "<>*RD*") / 1.0936 ))+_xlfn.IFNA(D140,0)} -> 8915.5084 | V19: {=(_xlfn.BYROW(B71,_xlfn.LAMBDA(_xlpm.party,SUMIFS(ledger!G:G,ledger!B:B,_xlpm.party,ledger!E:E,"<>*RD*",ledger!D:D,"Chamki")+SUMIFS(ledger!G:G, ledger!B:B, _xlpm.party, ledger!E:E, "<>*RD*", ledger!D:D, "Crinkle")))/1.0936)+_xlfn.IFNA(E140,0)} -> 8915.5084 | W19: {=(_xlfn.BYROW(B71,_xlfn.LAMBDA(_xlpm.party,SUMIFS(ledger!G:G,ledger!B:B,_xlpm.party,ledger!E:E,"<>*RD*",ledger!D:D,"Silky")))/1.0936)+_xlfn.IFNA(F140,0)} -> 0 | X19: {=(_xlfn.BYROW(B71,_xlfn.LAMBDA(_xlpm.party, (SUMIFS(ledger!J:J,ledger!B:B,_xlpm.party,ledger!E:E,"<>*RD*",ledger!D:D,"Chamki",ledger!C:C,"<>Closing CF")+ SUMIFS(ledger!J:J,ledger!B:B,_xlpm.party,ledger!E:E,"<>*RD*",ledger!D:D,"Crinkle",ledger!C:C,"<>Closing CF") )+_xlfn.IFNA(G140,0))))} -> 89155.084 | Y19: {=_xlfn.BYROW(B71, _xlfn.LAMBDA(_xlpm.party, SUMIFS(ledger!J:J, ledger!B:B, _xlpm.party, ledger!E:E, "<>*RD*", ledger!D:D, "Silky", ledger!C:C, "<>Closing CF") )) + _xlfn.IFNA(H140, 0)} -> 0 | Z19: {=_xlfn.BYROW(B71, _xlfn.LAMBDA(_xlpm.party, SUMIFS(ledger!J:J, ledger!B:B, _xlpm.party, ledger!E:E, "<>*RD*", ledger!D:D, "Slub", ledger!C:C, "<>Closing CF") ))+ _xlfn.IFNA(I140, 0)} -> 0 | AA19: {=_xlfn.BYROW(B71, _xlfn.LAMBDA(_xlpm.party, SUMIFS(ledger!J:J, ledger!B:B, _xlpm.party, ledger!E:E, "<>*RD*", ledger!D:D, "Satin", ledger!C:C, "<>Closing CF") ))+ _xlfn.IFNA(J140, 0)} -> 0 | AB19: {=_xlfn.BYROW(B71, _xlfn.LAMBDA(_xlpm.party, SUMIFS(ledger!J:J, ledger!B:B, _xlpm.party, ledger!E:E, "<>*RD*", ledger!D:D, "Black-Chamki", ledger!C:C, "<>Closing CF") ))+ _xlfn.IFNA(K140, 0)} -> 0 | AC19: {=_xlfn.BYROW(B71, _xlfn.LAMBDA(_xlpm.party, SUMIFS(ledger!J:J, ledger!B:B, _xlpm.party, ledger!E:E, "<>*RD*", ledger!D:D, "Kataan", ledger!C:C, "<>Closing CF") ))+ _xlfn.IFNA(L140, 0)} -> 0 | AD19: {=_xlfn.BYROW(B71, _xlfn.LAMBDA(_xlpm.party, SUMIFS(ledger!J:J, ledger!B:B, _xlpm.party, ledger!E:E, "<>*RD*", ledger!D:D, "Munaar", ledger!C:C, "<>Closing CF") ))+ _xlfn.IFNA(M140, 0)} -> 0 | AE19: {=_xlfn.BYROW(B71, _xlfn.LAMBDA(_xlpm.party, SUMIFS(ledger!J:J, ledger!B:B, _xlpm.party, ledger!E:E, "<>*RD*", ledger!D:D, "Super Kataan", ledger!C:C, "<>Closing CF") ))+ _xlfn.IFNA(N140, 0)} -> 0 | AF19: {=_xlfn.BYROW(B71, _xlfn.LAMBDA(_xlpm.party, SUMIFS(ledger!J:J, ledger!B:B, _xlpm.party, ledger!E:E, "<>*RD*", ledger!D:D, "Custom", ledger!C:C, "<>Closing CF") ))+ _xlfn.IFNA(O140, 0)} -> 0 | AG19: =X19+Y19+Z19+AA19+AB19+AC19+AD19+AF19+AE19 -> 89155.084 | AH19: =(SUMIF(Table14[Party],S19,Table14[Credit]))+_xlfn.IFNA(Q140,0) -> 95000 | AI19: =AG19-AH19 -> -5844.9159 | AJ19: 10 | AK19: 13
I20: Amjad sohail | S20: Haseeb Shamsi | T20: {=_xlfn.BYROW(B72,_xlfn.LAMBDA(_xlpm.party,SUMIFS(ledger!G:G,ledger!B:B,_xlpm.party,ledger!E:E,"<>*RD*")))+_xlfn.IFNA(C141,0)} -> 61975 | U20: {=_xlfn.BYROW(B72, _xlfn.LAMBDA(_xlpm.party, SUMIFS(ledger!G:G, ledger!B:B, _xlpm.party, ledger!E:E, "<>*RD*") / 1.0936 ))+_xlfn.IFNA(D141,0)} -> 56670.629 | V20: {=(_xlfn.BYROW(B72,_xlfn.LAMBDA(_xlpm.party,SUMIFS(ledger!G:G,ledger!B:B,_xlpm.party,ledger!E:E,"<>*RD*",ledger!D:D,"Chamki")+SUMIFS(ledger!G:G, ledger!B:B, _xlpm.party, ledger!E:E, "<>*RD*", ledger!D:D, "Crinkle")))/1.0936)+_xlfn.IFNA(E141,0)} -> 47437.82 | W20: {=(_xlfn.BYROW(B72,_xlfn.LAMBDA(_xlpm.party,SUMIFS(ledger!G:G,ledger!B:B,_xlpm.party,ledger!E:E,"<>*RD*",ledger!D:D,"Silky")))/1.0936)+_xlfn.IFNA(F141,0)} -> 9232.8091 | X20: {=(_xlfn.BYROW(B72,_xlfn.LAMBDA(_xlpm.party, (SUMIFS(ledger!J:J,ledger!B:B,_xlpm.party,ledger!E:E,"<>*RD*",ledger!D:D,"Chamki",ledger!C:C,"<>Closing CF")+ SUMIFS(ledger!J:J,ledger!B:B,_xlpm.party,ledger!E:E,"<>*RD*",ledger!D:D,"Crinkle",ledger!C:C,"<>Closing CF") )+_xlfn.IFNA(G141,0))))} -> 474378.2 | Y20: {=_xlfn.BYROW(B72, _xlfn.LAMBDA(_xlpm.party, SUMIFS(ledger!J:J, ledger!B:B, _xlpm.party, ledger!E:E, "<>*RD*", ledger!D:D, "Silky", ledger!C:C, "<>Closing CF") )) + _xlfn.IFNA(H141, 0)} -> 120026.52 | Z20: {=_xlfn.BYROW(B72, _xlfn.LAMBDA(_xlpm.party, SUMIFS(ledger!J:J, ledger!B:B, _xlpm.party, ledger!E:E, "<>*RD*", ledger!D:D, "Slub", ledger!C:C, "<>Closing CF") ))+ _xlfn.IFNA(I141, 0)} -> 0 | AA20: {=_xlfn.BYROW(B72, _xlfn.LAMBDA(_xlpm.party, SUMIFS(ledger!J:J, ledger!B:B, _xlpm.party, ledger!E:E, "<>*RD*", ledger!D:D, "Satin", ledger!C:C, "<>Closing CF") ))+ _xlfn.IFNA(J141, 0)} -> 0 | AB20: {=_xlfn.BYROW(B72, _xlfn.LAMBDA(_xlpm.party, SUMIFS(ledger!J:J, ledger!B:B, _xlpm.party, ledger!E:E, "<>*RD*", ledger!D:D, "Black-Chamki", ledger!C:C, "<>Closing CF") ))+ _xlfn.IFNA(K141, 0)} -> 0 | AC20: {=_xlfn.BYROW(B72, _xlfn.LAMBDA(_xlpm.party, SUMIFS(ledger!J:J, ledger!B:B, _xlpm.party, ledger!E:E, "<>*RD*", ledger!D:D, "Kataan", ledger!C:C, "<>Closing CF") ))+ _xlfn.IFNA(L141, 0)} -> 0 | AD20: {=_xlfn.BYROW(B72, _xlfn.LAMBDA(_xlpm.party, SUMIFS(ledger!J:J, ledger!B:B, _xlpm.party, ledger!E:E, "<>*RD*", ledger!D:D, "Munaar", ledger!C:C, "<>Closing CF") ))+ _xlfn.IFNA(M141, 0)} -> 0 | AE20: {=_xlfn.BYROW(B72, _xlfn.LAMBDA(_xlpm.party, SUMIFS(ledger!J:J, ledger!B:B, _xlpm.party, ledger!E:E, "<>*RD*", ledger!D:D, "Super Kataan", ledger!C:C, "<>Closing CF") ))+ _xlfn.IFNA(N141, 0)} -> 0 | AF20: {=_xlfn.BYROW(B72, _xlfn.LAMBDA(_xlpm.party, SUMIFS(ledger!J:J, ledger!B:B, _xlpm.party, ledger!E:E, "<>*RD*", ledger!D:D, "Custom", ledger!C:C, "<>Closing CF") ))+ _xlfn.IFNA(O141, 0)} -> 0 | AG20: =X20+Y20+Z20+AA20+AB20+AC20+AD20+AF20+AE20 -> 594404.72 | AH20: =(SUMIF(Table14[Party],S20,Table14[Credit]))+_xlfn.IFNA(Q141,0) -> 594405 | AI20: =AG20-AH20 -> -0.28163862 | AJ20: 10 | AK20: 13
B21: Total: | C21: =SUM(P57:P103) -> 52727241 | D21: (Real Figure) | I21: Salman Zaffar | S21: Faizan | T21: {=_xlfn.BYROW(B73,_xlfn.LAMBDA(_xlpm.party,SUMIFS(ledger!G:G,ledger!B:B,_xlpm.party,ledger!E:E,"<>*RD*")))+_xlfn.IFNA(C142,0)} -> 565150 | U21: {=_xlfn.BYROW(B73, _xlfn.LAMBDA(_xlpm.party, SUMIFS(ledger!G:G, ledger!B:B, _xlpm.party, ledger!E:E, "<>*RD*") / 1.0936 ))+_xlfn.IFNA(D142,0)} -> 516779.44 | V21: {=(_xlfn.BYROW(B73,_xlfn.LAMBDA(_xlpm.party,SUMIFS(ledger!G:G,ledger!B:B,_xlpm.party,ledger!E:E,"<>*RD*",ledger!D:D,"Chamki")+SUMIFS(ledger!G:G, ledger!B:B, _xlpm.party, ledger!E:E, "<>*RD*", ledger!D:D, "Crinkle")))/1.0936)+_xlfn.IFNA(E142,0)} -> 0 | W21: {=(_xlfn.BYROW(B73,_xlfn.LAMBDA(_xlpm.party,SUMIFS(ledger!G:G,ledger!B:B,_xlpm.party,ledger!E:E,"<>*RD*",ledger!D:D,"Silky")))/1.0936)+_xlfn.IFNA(F142,0)} -> 513809.44 | X21: {=(_xlfn.BYROW(B73,_xlfn.LAMBDA(_xlpm.party, (SUMIFS(ledger!J:J,ledger!B:B,_xlpm.party,ledger!E:E,"<>*RD*",ledger!D:D,"Chamki",ledger!C:C,"<>Closing CF")+ SUMIFS(ledger!J:J,ledger!B:B,_xlpm.party,ledger!E:E,"<>*RD*",ledger!D:D,"Crinkle",ledger!C:C,"<>Closing CF") )+_xlfn.IFNA(G142,0))))} -> 30000 | Y21: {=_xlfn.BYROW(B73, _xlfn.LAMBDA(_xlpm.party, SUMIFS(ledger!J:J, ledger!B:B, _xlpm.party, ledger!E:E, "<>*RD*", ledger!D:D, "Silky", ledger!C:C, "<>Closing CF") )) + _xlfn.IFNA(H142, 0)} -> 6679522.7 | Z21: {=_xlfn.BYROW(B73, _xlfn.LAMBDA(_xlpm.party, SUMIFS(ledger!J:J, ledger!B:B, _xlpm.party, ledger!E:E, "<>*RD*", ledger!D:D, "Slub", ledger!C:C, "<>Closing CF") ))+ _xlfn.IFNA(I142, 0)} -> 44550.11 | AA21: {=_xlfn.BYROW(B73, _xlfn.LAMBDA(_xlpm.party, SUMIFS(ledger!J:J, ledger!B:B, _xlpm.party, ledger!E:E, "<>*RD*", ledger!D:D, "Satin", ledger!C:C, "<>Closing CF") ))+ _xlfn.IFNA(J142, 0)} -> 0 | AB21: {=_xlfn.BYROW(B73, _xlfn.LAMBDA(_xlpm.party, SUMIFS(ledger!J:J, ledger!B:B, _xlpm.party, ledger!E:E, "<>*RD*", ledger!D:D, "Black-Chamki", ledger!C:C, "<>Closing CF") ))+ _xlfn.IFNA(K142, 0)} -> 0 | AC21: {=_xlfn.BYROW(B73, _xlfn.LAMBDA(_xlpm.party, SUMIFS(ledger!J:J, ledger!B:B, _xlpm.party, ledger!E:E, "<>*RD*", ledger!D:D, "Kataan", ledger!C:C, "<>Closing CF") ))+ _xlfn.IFNA(L142, 0)} -> 0 | AD21: {=_xlfn.BYROW(B73, _xlfn.LAMBDA(_xlpm.party, SUMIFS(ledger!J:J, ledger!B:B, _xlpm.party, ledger!E:E, "<>*RD*", ledger!D:D, "Munaar", ledger!C:C, "<>Closing CF") ))+ _xlfn.IFNA(M142, 0)} -> 0 | AE21: {=_xlfn.BYROW(B73, _xlfn.LAMBDA(_xlpm.party, SUMIFS(ledger!J:J, ledger!B:B, _xlpm.party, ledger!E:E, "<>*RD*", ledger!D:D, "Super Kataan", ledger!C:C, "<>Closing CF") ))+ _xlfn.IFNA(N142, 0)} -> 0 | AF21: {=_xlfn.BYROW(B73, _xlfn.LAMBDA(_xlpm.party, SUMIFS(ledger!J:J, ledger!B:B, _xlpm.party, ledger!E:E, "<>*RD*", ledger!D:D, "Custom", ledger!C:C, "<>Closing CF") ))+ _xlfn.IFNA(O142, 0)} -> 0 | AG21: =X21+Y21+Z21+AA21+AB21+AC21+AD21+AF21+AE21 -> 6754072.8 | AH21: =(SUMIF(Table14[Party],S21,Table14[Credit]))+_xlfn.IFNA(Q142,0) -> 6728187 | AI21: =AG21-AH21 -> 25885.787 | AJ21: 10 | AK21: 13
I22: Shahid Qasayi | S22: Shafique Ansari | T22: {=_xlfn.BYROW(B74,_xlfn.LAMBDA(_xlpm.party,SUMIFS(ledger!G:G,ledger!B:B,_xlpm.party,ledger!E:E,"<>*RD*")))+_xlfn.IFNA(C143,0)} -> 517899 | U22: {=_xlfn.BYROW(B74, _xlfn.LAMBDA(_xlpm.party, SUMIFS(ledger!G:G, ledger!B:B, _xlpm.party, ledger!E:E, "<>*RD*") / 1.0936 ))+_xlfn.IFNA(D143,0)} -> 473572.6 | V22: {=(_xlfn.BYROW(B74,_xlfn.LAMBDA(_xlpm.party,SUMIFS(ledger!G:G,ledger!B:B,_xlpm.party,ledger!E:E,"<>*RD*",ledger!D:D,"Chamki")+SUMIFS(ledger!G:G, ledger!B:B, _xlpm.party, ledger!E:E, "<>*RD*", ledger!D:D, "Crinkle")))/1.0936)+_xlfn.IFNA(E143,0)} -> 90599.854 | W22: {=(_xlfn.BYROW(B74,_xlfn.LAMBDA(_xlpm.party,SUMIFS(ledger!G:G,ledger!B:B,_xlpm.party,ledger!E:E,"<>*RD*",ledger!D:D,"Silky")))/1.0936)+_xlfn.IFNA(F143,0)} -> 78055.962 | X22: {=(_xlfn.BYROW(B74,_xlfn.LAMBDA(_xlpm.party, (SUMIFS(ledger!J:J,ledger!B:B,_xlpm.party,ledger!E:E,"<>*RD*",ledger!D:D,"Chamki",ledger!C:C,"<>Closing CF")+ SUMIFS(ledger!J:J,ledger!B:B,_xlpm.party,ledger!E:E,"<>*RD*",ledger!D:D,"Crinkle",ledger!C:C,"<>Closing CF") )+_xlfn.IFNA(G143,0))))} -> 932297.92 | Y22: {=_xlfn.BYROW(B74, _xlfn.LAMBDA(_xlpm.party, SUMIFS(ledger!J:J, ledger!B:B, _xlpm.party, ledger!E:E, "<>*RD*", ledger!D:D, "Silky", ledger!C:C, "<>Closing CF") )) + _xlfn.IFNA(H143, 0)} -> 980700.44 | Z22: {=_xlfn.BYROW(B74, _xlfn.LAMBDA(_xlpm.party, SUMIFS(ledger!J:J, ledger!B:B, _xlpm.party, ledger!E:E, "<>*RD*", ledger!D:D, "Slub", ledger!C:C, "<>Closing CF") ))+ _xlfn.IFNA(I143, 0)} -> 0 | AA22: {=_xlfn.BYROW(B74, _xlfn.LAMBDA(_xlpm.party, SUMIFS(ledger!J:J, ledger!B:B, _xlpm.party, ledger!E:E, "<>*RD*", ledger!D:D, "Satin", ledger!C:C, "<>Closing CF") ))+ _xlfn.IFNA(J143, 0)} -> 470003.66 | AB22: {=_xlfn.BYROW(B74, _xlfn.LAMBDA(_xlpm.party, SUMIFS(ledger!J:J, ledger!B:B, _xlpm.party, ledger!E:E, "<>*RD*", ledger!D:D, "Black-Chamki", ledger!C:C, "<>Closing CF") ))+ _xlfn.IFNA(K143, 0)} -> 0 | AC22: {=_xlfn.BYROW(B74, _xlfn.LAMBDA(_xlpm.party, SUMIFS(ledger!J:J, ledger!B:B, _xlpm.party, ledger!E:E, "<>*RD*", ledger!D:D, "Kataan", ledger!C:C, "<>Closing CF") ))+ _xlfn.IFNA(L143, 0)} -> 2653520.5 | AD22: {=_xlfn.BYROW(B74, _xlfn.LAMBDA(_xlpm.party, SUMIFS(ledger!J:J, ledger!B:B, _xlpm.party, ledger!E:E, "<>*RD*", ledger!D:D, "Munaar", ledger!C:C, "<>Closing CF") ))+ _xlfn.IFNA(M143, 0)} -> 0 | AE22: {=_xlfn.BYROW(B74, _xlfn.LAMBDA(_xlpm.party, SUMIFS(ledger!J:J, ledger!B:B, _xlpm.party, ledger!E:E, "<>*RD*", ledger!D:D, "Super Kataan", ledger!C:C, "<>Closing CF") ))+ _xlfn.IFNA(N143, 0)} -> 0 | AF22: {=_xlfn.BYROW(B74, _xlfn.LAMBDA(_xlpm.party, SUMIFS(ledger!J:J, ledger!B:B, _xlpm.party, ledger!E:E, "<>*RD*", ledger!D:D, "Custom", ledger!C:C, "<>Closing CF") ))+ _xlfn.IFNA(O143, 0)} -> 701356.99 | AG22: =X22+Y22+Z22+AA22+AB22+AC22+AD22+AF22+AE22 -> 5737879.5 | AH22: =(SUMIF(Table14[Party],S22,Table14[Credit]))+_xlfn.IFNA(Q143,0) -> 4935017 | AI22: =AG22-AH22 -> 802862.48 | AJ22: 10 | AK22: 13
